Workbook

Sheet Pivot
A3: Count of ToolNumber | B3: Column Labels
B4: 1 | NA4: 2 | AAR4: 3 | AAT4: Grand Total
A5: Row Labels | B5: .122066KIT | C5: 1.00-SPADE-INS | D5: 1.00SPOTDRL | E5: 1.00SPOT-DRL-1 | F5: 1.750INS-DRL | G5: 1/16DRL | H5: 1/2-13-H3-PLG | I5: 1/2-13-SPLK-BTM-TAP | J5: 1/2-20-4FL-BTM | K5: 1/2-20-H11-BTM | L5: 1/2-2FL-CEM | M5: 1/2DRL | N5: 1/2FEROCIOUS-CEM | O5: 1/2SPOTDRL | P5: 1/4-20-2FL-H11-PLG | Q5: 1/4-20-SPLK-PLG-TAP | R5: 1/4-2FL-BALL-CEM | S5: 1/4-2FL-BALL-HSSEM | T5: 1/4-2FL-CEM | U5: 1/4DRL | V5: 1/4SPOTDRL | W5: 1/8-27-NPT-EXT | X5: 1/8-2FL-CEM | Y5: 1/8-DRL | Z5: 10-24-H11-PLG | AA5: 10-24-SPLK-2FL-PLG-TAP | AB5: 10-24-SPLK-BTM-TAP | AC5: 105691J | AD5: 10PITCHKNURL | AE5: 1-1/16BROACH | AF5: 11/16CBT-S+D-DRL | AG5: 11/16CLT-DRL-3/4SHK | AH5: 11/16DRL | AI5: 1-1/16DRL | AJ5: 11/16SMDRL | AK5: 1-1/16-SPADE-INS | AL5: 11/32CBD | AM5: 11/32DRL | AN5: 1-1/4-SPADE-INS | AO5: 1-1/8-SPADE-INS | AP5: 110078J | AQ5: 115232J | AR5: 117463-BOLT | AS5: 121907J | AT5: 122391J | AU5: 13/16BROACH | AV5: 13/16DRL | AW5: 1-3/16-SPADE-INS | AX5: 13/32CBD | AY5: 13/32DRL | AZ5: 13/64DRL | BA5: 15/32CBT-DRL | BB5: 17/64CBD | BC5: 18.00MM-SS-DRL | BD5: 19/32CBT-DRL | BE5: 19/32DRL | BF5: 2" BASE GROOVE BAR | BG5: 20PITCHKNURL | BH5: 22010S-100L-SPADE | BI5: 22020S-100L-SPADE | BJ5: 23/32CBT-DRL | BK5: 23/32SMDRL | BL5: 23010S-100L-SPADE | BM5: 23020S-125L-SPADE | BN5: 24010S-100L-SPADE | BO5: 25/64SMDRL | BP5: 29/64CBD | BQ5: 29/64SMDRL | BR5: 3.3MMDRL | BS5: 3/16-2FL-BALL-CEM | BT5: 3/16CBT-DRL | BU5: 3/16DRL | BV5: 3/16SPOTDRL | BW5: 3/4-16-H11-PLG | BX5: 3/4-2FL-CEM-TIN-COAT | BY5: 3/4-4FL-HSSEM | BZ5: 3/4DRL | CA5: 3/4-SPADE-INS | CB5: 3/4SPOTDRL | CC5: 3/8-16-EXT-H3-PLG | CD5: 3/8-16-EXT-SPLK-TAP | CE5: 3/8-16-SPLK-BTM-TAP | CF5: 3/8-24-H3-3FL-BTM | CG5: 3/8-2FL-BALL-CEM | CH5: 3/8-2FL-CEM | CI5: 3/8SPOTDRL | CJ5: 33/64-4FL-HSSEM | CK5: 33/64CBT-DRL | CL5: 33/64DRL | CM5: 33/64SMDRL | CN5: 35/64SMDRL | CO5: 37/64SMDRL | CP5: 4.00X.125-MLCTR | CQ5: 40007770J | CR5: 40075669J | CS5: 40081503J | CT5: 40084897J | CU5: 40085549J | CV5: 43/64TSDRL | CW5: 4303-C2F | CX5: 4-40-H11-PLG | CY5: 45/64SMDRL | CZ5: 5/16-24-H11-PLG | DA5: 5/16-2FL-CEM | DB5: 5/16DRL | DC5: 5/32DRL | DD5: 5/64-2FL-CEM | DE5: 5/64DRL | DF5: 5/8-18-4FL-BTM | DG5: 5/8-18-H11-PLG | DH5: 5/8-2FL-CEM | DI5: 5/8CLT-DRL | DJ5: 5/8DRL | DK5: 5/8SPOTDRL | DL5: 5973 | DM5: 6.4MM-CBT | DN5: 7/16-14-H3-4FL-BTM | DO5: 7/16CBT-DRL | DP5: 7/16DRL | DQ5: 7/32CBT-DRL | DR5: 7/8-SPADE-INS | DS5: 9/16-18-H11-BTM | DT5: 9/16-18-H11-PLG | DU5: 9/16-18-SPLK-BTM-TAP | DV5: 9/16CBTDRL | DW5: 9/16DRL | DX5: 9/32CBD | DY5: 9/32CBT-DRL | DZ5: A12NER2 | EA5: A12RA4EMR0307N | EB5: A12SCFPR3 | EC5: A16DCLNR4SS | ED5: A16NER3 | EE5: A16RA4EMR0410N | EF5: A16SDUCR3 | EG5: A16SVUBR3 | EH5: A20-DCLNR4 | EI5: A20MVUNR3 | EJ5: A20SA4EMR0412N | EK5: A24MDUNR4 | EL5: A24TA4EMR0416N | EM5: A32DCLNR | EN5: A3M50R326M | EO5: A4G0305M03U02GMN | EP5: A4G0405M04U04GMN | EQ5: A4G187I04P1GMN | ER5: A4M50R0314M | ES5: A4M50R0414M | ET5: A4R187I04P00GMN | EU5: ASSTLIVECENTERS | EV5: AT-10429L | EW5: AT-116A | EX5: B-1212 | EY5: B-3112-S | EZ5: BT-10939 | FA5: BT-11390 | FB5: BT-12340 | FC5: BT-12450 | FD5: BT-12723 | FE5: BT-13188 GAUGE | FF5: BT-1947-1 | FG5: BT-1947-2 | FH5: BT-1947-31 | FI5: BT-1947-8 | FJ5: BT-4301-6P-4T | FK5: BT-4302-11.5P-3T | FL5: BT-4302-11.5P-5T | FM5: BT-4303 | FN5: BT-4303-1 | FO5: BT-4303-7.5P-4T | FP5: BT-4303-7.5P-5T | FQ5: BT-4306-8P-7T | FR5: BT-4308 | FS5: BT-4309-9P-3T | FT5: BT-4309-9P-4T | FU5: BT-4314 | FV5: BT-4317-8P-5T | FW5: BT-5365 | FX5: BT-5365-11P-4T | FY5: BT-7203 | FZ5: C10SCLPR3-4 | GA5: C10SCLPR3-5 | GB5: C10SCLPR3-7 | GC5: C12SCLPR3-4 | GD5: C12SCLPR3-5 | GE5: C12SCLPR3-6 | GF5: C12SCLPR3-7 | GG5: C12SDUCR3 | GH5: C16-SCLPR3 | GI5: C16SCLPR3-4 | GJ5: C16SCLPR3-5 | GK5: C16SCLPR3-6 | GL5: C16SCLPR3-7 | GM5: C16SCLPR3X4 | GN5: C8SCLPR2-3 | GO5: C8SCLPR2-5 | GP5: CB3B | GQ5: CCGT4305HP | GR5: CHUCK-JAWKEYS | GS5: CNMG431 | GT5: CNMG432MLK10 | GU5: CNMG432MP-BRASS | GV5: CNMS432 | GW5: CNMS643 | GX5: CPMT2152LF | GY5: CPMT3250.5LF | GZ5: CPMT3251LF | HA5: CPMT3252LF | HB5: CPMT3252LF-CAP | HC5: CT-11397J | HD5: CT-12190-1J | HE5: CT-4811J | HF5: CT-5248-129 | HG5: CT-5248-132 | HH5: CT-5248-155 | HI5: CT-5248-164 | HJ5: CT-5248-19 | HK5: CT-6557-1J-NTX | HL5: CT-7346-3 | HM5: CT-8058J | HN5: DA-C08-500-LONG | HO5: DA-C16-1-INCH-LONG | HP5: DA-DT-12803 | HQ5: DA-E6-375-SHORT | HR5: DA-KGMSR-OD-A4 | HS5: DA-LIVE-X-HEAD | HT5: DA-LIVE-Z-HEAD | HU5: DA-TRIGON-POST | HV5: DCLNR164DKC | HW5: DDJNR164C | HX5: DGFH32-3 | HY5: DGNM-3202C | HZ5: DNMG432 | IA5: DNMS432 | IB5: DNMS432-K68 | IC5: DORTO1MS-10-HS | ID5: DPMT3252LF | IE5: DT-10170 | IF5: DT-10997J | IG5: DT-12375-HCJ | IH5: DT-12507 | II5: DT-12509 | IJ5: DT-12617 | IK5: DT-12848J | IL5: DT-12944 | IM5: DT-13047J | IN5: DT-13838-NTX | IO5: DT-13845-NTX | IP5: DT-13969 | IQ5: DVJNR163DKC3 | IR5: E16NER3 | IS5: E16SCLPR3 | IT5: E6SCLPR2 | IU5: EA-BOREBAR-EXT | IV5: EG125I03U05GUN | IW5: EVM50R0316MC | IX5: EVM50R0326MC | IY5: GFG188 | IZ5: HARD-JAWS-SMALL | JA5: HARD-JAWS-STD | JB5: ISCAR-SGTBU-CUTOFF | JC5: KBCR-CUTOFF | JD5: KEN1096448 | JE5: KGMSL165SN | JF5: KGMSR1650N | JG5: KIPR125XD-ENDMILL | JH5: KISR125LF | JI5: KM40-NRR3 | JJ5: K-TOOLSDCS901A1M | JK5: K-TOOLSDCS901L | JL5: K-TOOL-SDCS90-500 | JM5: K-TOOLSDCS90-500GR | JN5: K-TOOLSDCS90-750 | JO5: K-TOOLSDCS-90-750-A1M | JP5: LFEW-2521-FRLN | JQ5: LIVE-X | JR5: LIVE-Z | JS5: LSASR12 | JT5: LSASR163-LAYDN-THD | JU5: LT16ER18UN | JV5: LTR.H.CBD | JW5: LTR.P.DRL | JX5: LTR.Q.DRL | JY5: LTR.U.DRL | JZ5: M8X125-PLG-TAP | KA5: MAFORD-1-INCH-CHMF | KB5: MCHR-218-126 | KC5: MCHR-338-102 | KD5: MCHR-506-101-20 | KE5: MCHR-510-117-36 | KF5: MWLNR164C | KG5: N02886 | KH5: NG2125LK | KI5: NG3047R | KJ5: NG3062LK | KK5: NG3062RK | KL5: NG3094RK | KM5: NG3125L | KN5: NG3125LK | KO5: NG3125R | KP5: NG3125RK | KQ5: NG3189L | KR5: NG3189R | KS5: NO.02DRL | KT5: NO.03DRL | KU5: NO.04DRL | KV5: NO.09DRL | KW5: NO.11DRL | KX5: NO.20DRL | KY5: NO.21DRL | KZ5: NO.23DRL | LA5: NO.24DRL | LB5: NO.2CD6 | LC5: NO.30CBT-DRL | LD5: NO.30EXL-DRL | LE5: NO.41DRL | LF5: NO.46DRL | LG5: NO.4CBT-DRL | LH5: NR3031R | LI5: NR3062L | LJ5: NR3062R | LK5: NR4062L | LL5: NR4125L | LM5: NSL163C | LN5: NSR163C | LO5: NSR164C | LP5: NT2L | LQ5: NT3L | LR5: NT3R | LS5: NTP3R | LT5: NWC-3L11I | LU5: SOLID-ID-BLOCK | LV5: SPMX-1504AP-75 | LW5: SSO75ER16700 | LX5: STOPBLOCK100 | LY5: STOPBLOCK1125 | LZ5: STOPBLOCK1250 | MA5: STOPBLOCK1375 | MB5: STOPBLOCK1500 | MC5: STOPBLOCK1625 | MD5: STOPBLOCK1750 | ME5: STOPBLOCK500 | MF5: STOPBLOCK750 | MG5: SUPERSTUBBY2A24 | MH5: T-404-CONICAL-E-MILL | MI5: TAE-2830078 | MJ5: TDJ4-15L | MK5: TF25423A3 | ML5: TPG432 | MM5: TRIGON-OD-TURN | MN5: VAL100XTN | MO5: VAL750XTN | MP5: VNGP330.5 | MQ5: VNMG332 | MR5: VNMG332MP | MS5: VNMG432 | MT5: VNMS332 | MU5: VNMS-332 | MV5: WCMX080412-85 | MW5: WNMG432MP | MX5: WNMG432MP KC 5010 | MY5: X6030000X012080 | MZ5: XDMT2322R | NA5: 0087374J | NB5: 1/2-13-H3-PLG | NC5: 1/2-2FL-CEM | ND5: 1/2-2FL-EXL-CEM | NE5: 1/2SPOTDRL | NF5: 1/4-20 H10 FORM TAP | NG5: 1/4-20-GH11-DRAP | NH5: 1/4-20-H11-BTM-OSG | NI5: 1/4-20-H11-EXT-PLG-TAP | NJ5: 1/4-20-H3-2FL-PLG | NK5: 1/4-20-H3-BTM | NL5: 1/4-20-SPLK-PLG-TAP | NM5: 1/4SPOTDRL | NN5: 101944 | NO5: 102067 | NP5: 102084L | NQ5: 10-24 H10 FORM TAP | NR5: 10-24-EXT-H3-PLG | NS5: 10-24-H11-4FL-BTM | NT5: 10-24-H11-PLG | NU5: 10-24-H3-2FL-PLG | NV5: 10-24-SPLK-2FL-PLG-TAP | NW5: 104576L | NX5: 105691J | NY5: 105990L | NZ5: 106859J | OA5: 108033L | OB5: 108166-RING | OC5: 109477GB | OD5: 11/16SMDRL | OE5: 11/32-2FL-CEM | OF5: 110171J | OG5: 115606 | OH5: 115987L | OI5: 117077 | OJ5: 117605L | OK5: 117901-NTX | OL5: 117946-NTX | OM5: 118764J | ON5: 122104J | OO5: 122391-2 | OP5: 122391J | OQ5: 124357L-NTX | OR5: 126160-2L-NTX | OS5: 126532 | OT5: 127160L | OU5: 127720L-NTX | OV5: 13/64DRL | OW5: 15/32CBD | OX5: 17/32CBD | OY5: 2.60MM-OSG | OZ5: 23/32SMDRL | PA5: 3/16-2FL-CEM | PB5: 3/16-2FL-DE-BALL-HSSEM | PC5: 3/16CBT-DRL | PD5: 3/4-2FL-CEM-TIN-COAT | PE5: 3/4SPOTDRL | PF5: 3/8-16-EXT-H11-PLG | PG5: 3/8-16-EXT-H3-BTM | PH5: 3/8-16-EXT-H3-PLG | PI5: 3/8-16-EXT-SPLK-TAP | PJ5: 3/8-16-H11-PLG | PK5: 3/8-16-H3-3FL-BTM | PL5: 3/8-16-H3-PLG | PM5: 3/8-24-H11-2FL-BTM | PN5: 3/8-2FL-CEM | PO5: 3/8SPOTDRL | PP5: 37/64DRL | PQ5: 40010182J | PR5: 40011107L | PS5: 40022400J | PT5: 40058853J | PU5: 40059798J | PV5: 40086213J-NTX | PW5: 5/16CBT-DRL | PX5: 5/16DRL | PY5: 5/16SMDRL | PZ5: 5/8-11-H11-PLG | QA5: 5/8-18-H3-EXT | QB5: 6.4MMDRL | QC5: 6-32-H11-3FL-PLG | QD5: 6-32-H11-PLG | QE5: 6-32-H3-3FL-PLG | QF5: 6-32-H3-PLG | QG5: 7/16DRL | QH5: 7/32-2FL-CEM | QI5: 8-32-H11-PLG | QJ5: A10NER2-SHORT | QK5: A12NER2 | QL5: A16DCLNR4SS | QM5: A16NER3 | QN5: A24MDUNR4 | QO5: A24TA4EMR0416N | QP5: A24TA4EMRO416N | QQ5: A4-1.250-GROOVE | QR5: A4G0305M03U02GMN | QS5: A4G0405M04U04GMN | QT5: A4G0405M04U08GMN | QU5: A4M50R0414M | QV5: A4R187I04P00GMN | QW5: A8NER2 | QX5: AC102 | QY5: AC203 | QZ5: AC2110 | RA5: AC2210 | RB5: AC2410 | RC5: AC2510 | RD5: AC2610 | RE5: AC2710 | RF5: AC2810 | RG5: AC2910 | RH5: AC401 | RI5: AC403 | RJ5: AC409 | RK5: AC501 | RL5: AC505 | RM5: AC509 | RN5: AC513 | RO5: AC602 | RP5: AC606 | RQ5: AC610 | RR5: AC614 | RS5: AC615 | RT5: AC703 | RU5: AC715 | RV5: AC716 | RW5: AC718 | RX5: AC719 | RY5: AC720 | RZ5: AC721 | SA5: AC726 | SB5: AC727 | SC5: AC803 | SD5: AC813 | SE5: AC815 | SF5: AC901 | SG5: AC907 | SH5: AC908 | SI5: AC911 | SJ5: AC913 | SK5: AC915 | SL5: AC923 | SM5: AC924 | SN5: AC927 | SO5: AC928 | SP5: AC929 | SQ5: AC931 | SR5: ADKT16221 | SS5: BT-10251 | ST5: BT-10939 | SU5: BT-11376 | SV5: BT-11390 | SW5: BT-11417 | SX5: BT-12340 | SY5: BT-12450 | SZ5: BT-12678 | TA5: BT-12683 | TB5: BT-13022L-NTX | TC5: BT-1947 | TD5: BT-1947-1 | TE5: BT-1947-2 | TF5: BT-1947-9 | TG5: BT-3208-2 | TH5: BT-3890-1 | TI5: BT-3974 | TJ5: BT-4302-11.5P-5T | TK5: BT-4303-7.5P-4T | TL5: BT-4303-7.5P-5T | TM5: BT-4308-8P-3T | TN5: BT-4314 | TO5: BT-5365-11P-4T | TP5: BT-5722-12 | TQ5: BT-7203 | TR5: BT-7315L | TS5: BT-8767 | TT5: BT-8837 | TU5: C10SCLPR2-4 | TV5: C10SCLPR3-4 | TW5: C10SCLPR3-5 | TX5: C12SCLPR3-4 | TY5: C12SCLPR3-7 | TZ5: C12SDUCR3 | UA5: C16SCLPR3-4 | UB5: C16SCLPR3-5 | UC5: C16SCLPR3-6 | UD5: C16SCLPR3-7 | UE5: C16SCLPR3X4 | UF5: C6SCLPR2 | UG5: C8SCLPR2 | UH5: C8SCLPR2-3 | UI5: C8SCLPR2-4 | UJ5: C8SCLPR2-5 | UK5: C8SCLPR3-4 | UL5: CNGP432-ALUM | UM5: CNMG432MF | UN5: CNMG432MLK10 | UO5: CNMG432MP-BRASS | UP5: CNMG434RP | UQ5: CNMS432 | UR5: CPGT3252HP | US5: CPMT2151LF | UT5: CPMT2152LF | UU5: CPMT3251LF | UV5: CPMT3252LF | UW5: CPMT3252LF-CAP | UX5: CT-11160 | UY5: CT-11375 | UZ5: CT-11409 | VA5: CT-11418 | VB5: CT-11549-20 | VC5: CT-11849 | VD5: CT-5248-130 | VE5: CT-5248-85 | VF5: CT-5533L | VG5: CT-6002-1 | VH5: CT-6002-21 | VI5: CT-6003-10 | VJ5: CT-6003-7 | VK5: CT-6004-10 | VL5: CT-6004-12 | VM5: CT-6004-21 | VN5: CT-6004-24 | VO5: CT-6004-29 | VP5: CT-6004-31 | VQ5: CT-6004-34 | VR5: CT-6005-12 | VS5: CT-6005-13 | VT5: CT-6005-4-NTX | VU5: CT-6006-4 | VV5: CT-6006-7 | VW5: CT-6545-2 | VX5: CT-7517-1 | VY5: CT-7961-NTX | VZ5: CT-8904 | WA5: DA-C08-500-SHORT | WB5: DA-C16-1-INCH-LONG | WC5: DA-DT-12803 | WD5: DA-E6-375-SHORT | WE5: DA-KGMSR-OD-A4 | WF5: DA-LIVE-X-HEAD | WG5: DA-LIVE-Z-HEAD | WH5: DA-TRIGON-POST | WI5: DCGX-3252AL | WJ5: DCLNR164DKC | WK5: DDJNR164C | WL5: DGFH32-3 | WM5: DGNM-3202C | WN5: DNMG432 | WO5: DNMS432 | WP5: DT-10236-1 | WQ5: DT-11628 | WR5: DT-11628-XL | WS5: DT-12104 | WT5: DT-12260 | WU5: DT-12458 | WV5: DT-12693 | WW5: DT-12896L-NTX | WX5: DT-12983 | WY5: DT-13019L | WZ5: DT-13171-1 | XA5: DT-13171-2 | XB5: DT-13194 | XC5: DT-13216 | XD5: DT-13531 | XE5: DT-13532 | XF5: DT-13534-NTX | XG5: DT-13589-NTX | XH5: DT-13845-NTX | XI5: DT-13915-NTX | XJ5: DT-14021 | XK5: DVJNL163C | XL5: DVJNR163DKC3 | XM5: ER125I03P00GUP | XN5: EVM50R0312MC | XO5: EVM50R0316MC | XP5: EVM50R0326MC | XQ5: GFG125CC | XR5: HARD-JAWS-STD | XS5: ISCAR FACE GROOVE INSERT | XT5: ISCAR INT FACE GROOVE BLADE #8 | XU5: ISCAR INT RH FACE GROOVE BAR | XV5: ISCAR-SGTBU-CUTOFF | XW5: KGMSL165SN | XX5: KGMSR1650N | XY5: KISR100AD | XZ5: KISR125LF | YA5: K-TOOLSDCS901A1M | YB5: K-TOOL-SDCS90-500 | YC5: K-TOOLSDCS90-500GR | YD5: LFEW-2521-FRLN | YE5: LIVE-X | YF5: LIVE-Z | YG5: LTR.O.DRL | YH5: LTR.P.DRL | YI5: MCHR-218-121 | YJ5: MCHR-235-101 | YK5: MCHR-338-101 | YL5: MCHR-440-101 | YM5: MCHR-510-117-36 | YN5: MWLNR164C | YO5: NG2094LK | YP5: NG2125LK | YQ5: NG3062LK | YR5: NG3062R | YS5: NG3094LK KC5010 | YT5: NG3094R | YU5: NG3125L | YV5: NG3125LK | YW5: NG3125R | YX5: NG3125RK | YY5: NG3189R | YZ5: NG4250R | ZA5: NO.01DRL | ZB5: NO.07DRL | ZC5: NO.10DRL | ZD5: NO.18DRL | ZE5: NO.21DRL | ZF5: NO.23DRL | ZG5: NO.25DRL | ZH5: NO.25EXL-DRL | ZI5: NO.28DRL | ZJ5: NO.30CBT-DRL | ZK5: NO.33DRL | ZL5: NO.34DRL | ZM5: NO.35DRL | ZN5: NO.36DRL | ZO5: NO.4 CBT | ZP5: NO.41DRL | ZQ5: NO.4CBT-DRL | ZR5: NO.5CD2 | ZS5: NO.7CBD | ZT5: NO.7SMDRL | ZU5: NR3031R | ZV5: NR3062L | ZW5: NR3062R | ZX5: NSL163C | ZY5: NSR163C | ZZ5: NSR164C | AAA5: NT2L | AAB5: NT3L | AAC5: NT3R | AAD5: NTP2L | AAE5: NTP3L | AAF5: NTP3R | AAG5: NWC-3R11E | AAH5: SOLID-ID-BLOCK | AAI5: STOPBLOCK1250 | AAJ5: SUPERSTUBBY2A12 | AAK5: TRIGON-OD-TURN | AAL5: VNGP330.5 | AAM5: VNMG332 | AAN5: VNMG332MP | AAO5: VNMS332 | AAP5: VNMS-332 | AAQ5: WNMG432MP | AAR5: .500-1/2-CBORE | AAS5: 5/32EXL-DRL
A6: 03300003 | ED6: 1 | GI6: 1 | GU6: 1 | HA6: 1 | HV6: 1 | JA6: 1 | LQ6: 1 | MC6: 1 | TI6: 1 | UZ6: 1 | XL6: 1 | YY6: 1 | ZY6: 2 | AAF6: 1 | AAM6: 1 | AAT6: 16
A7: 03300005 | ED7: 1 | GI7: 1 | GU7: 1 | HA7: 1 | HV7: 1 | JA7: 1 | LQ7: 1 | MC7: 1 | TI7: 1 | UZ7: 1 | XL7: 1 | YY7: 1 | ZY7: 2 | AAF7: 1 | AAM7: 1 | AAT7: 16
A8: 03360009 | FP8: 1 | GJ8: 1 | GV8: 1 | HA8: 1 | HT8: 1 | HV8: 1 | JA8: 1 | KP8: 1 | LN8: 1 | LX8: 1 | MM8: 1 | MW8: 1 | RE8: 1 | RW8: 1 | TL8: 1 | UA8: 1 | UQ8: 1 | UV8: 1 | VN8: 1 | WC8: 1 | WG8: 1 | WJ8: 1 | YX8: 1 | ZY8: 1 | AAK8: 1 | AAQ8: 1 | AAT8: 26
A9: 100217 | GC9: 1 | GV9: 1 | HA9: 1 | HV9: 1 | JA9: 1 | KP9: 1 | LN9: 1 | MD9: 1 | RC9: 1 | RL9: 1 | TT9: 1 | TX9: 1 | UQ9: 1 | UV9: 1 | WC9: 1 | WJ9: 1 | YX9: 1 | ZY9: 1 | AAT9: 18
A10: 100728 | ED10: 1 | FB10: 1 | GI10: 1 | GV10: 1 | HA10: 1 | HC10: 1 | HT10: 1 | HV10: 1 | KM10: 1 | LJ10: 1 | LN10: 1 | AAT10: 11
A11: 100733 | ED11: 1 | FB11: 1 | GI11: 1 | GV11: 1 | HA11: 1 | HC11: 1 | HT11: 1 | HV11: 1 | KM11: 1 | LJ11: 1 | LN11: 1 | AAT11: 11
A12: 100735 | ED12: 1 | FO12: 1 | GI12: 1 | GV12: 1 | HA12: 1 | HD12: 1 | HT12: 1 | HV12: 1 | KM12: 1 | LJ12: 1 | LN12: 1 | AAT12: 11
A13: 100743 | ED13: 1 | FK13: 1 | GI13: 1 | GV13: 1 | HA13: 1 | HC13: 1 | HT13: 1 | HV13: 1 | KM13: 1 | LJ13: 1 | LN13: 1 | AAT13: 11
A14: 100746 | ED14: 1 | FL14: 1 | GM14: 1 | GV14: 1 | HA14: 1 | HC14: 1 | HV14: 1 | JR14: 1 | KM14: 1 | LJ14: 1 | LN14: 1 | AAT14: 11
A15: 101944 | GI15: 1 | HA15: 1 | IQ15: 1 | IZ15: 1 | LN15: 1 | LS15: 1 | LZ15: 1 | MU15: 1 | NN15: 1 | RE15: 1 | RX15: 1 | TK15: 1 | UA15: 1 | UV15: 1 | VM15: 1 | WG15: 1 | WQ15: 1 | XL15: 1 | AAP15: 1 | AAT15: 19
A16: 102067 | AI16: 1 | DJ16: 1 | EA16: 1 | EO16: 1 | GL16: 1 | GT16: 1 | HA16: 1 | HV16: 1 | JA16: 1 | JC16: 1 | JR16: 2 | LX16: 1 | NO16: 1 | RG16: 1 | SH16: 1 | UD16: 1 | UN16: 1 | UV16: 1 | WJ16: 1 | AAT16: 20
A17: 102084 | O17: 1 | AB17: 1 | AV17: 1 | FZ17: 1 | GV17: 1 | HA17: 1 | HJ17: 1 | HT17: 4 | HV17: 1 | HX17: 1 | HY17: 1 | JA17: 1 | JB17: 1 | KX17: 1 | LU17: 1 | MA17: 1 | NP17: 1 | RB17: 1 | RH17: 1 | TV17: 1 | UQ17: 1 | UV17: 1 | WJ17: 1 | AAT17: 26
A18: 102091 | X18: 1 | EN18: 1 | EO18: 1 | GD18: 1 | GV18: 1 | HA18: 1 | HV18: 1 | JA18: 1 | JF18: 1 | JR18: 1 | JT18: 1 | JU18: 1 | KK18: 1 | LN18: 1 | MC18: 1 | AAT18: 15
A19: 102091C | X19: 1 | GJ19: 1 | GV19: 1 | HA19: 1 | HV19: 1 | HX19: 1 | HY19: 1 | JA19: 1 | JB19: 1 | JR19: 1 | JT19: 1 | JU19: 1 | KK19: 1 | LN19: 1 | MC19: 1 | AAT19: 15
A20: 102149 | CF20: 1 | CI20: 1 | ED20: 1 | GI20: 1 | GV20: 1 | HA20: 1 | HS20: 3 | HV20: 1 | IZ20: 1 | JX20: 1 | LI20: 1 | PC20: 1 | PO20: 1 | RG20: 1 | SK20: 1 | SW20: 1 | UA20: 1 | UQ20: 1 | UV20: 1 | VA20: 1 | WC20: 1 | WG20: 2 | WJ20: 1 | YV20: 1 | YX20: 1 | ZY20: 2 | AAF20: 1 | AAT20: 31
A21: 102314 | BS21: 1 | CB21: 1 | CH21: 1 | FG21: 1 | GI21: 1 | GV21: 1 | HA21: 1 | HS21: 3 | HT21: 1 | HV21: 1 | IZ21: 1 | KG21: 1 | KP21: 1 | LJ21: 1 | LN21: 2 | LU21: 1 | LZ21: 1 | NZ21: 1 | PE21: 1 | QR21: 1 | TE21: 1 | UA21: 1 | UQ21: 1 | UV21: 1 | VE21: 1 | WJ21: 1 | XO21: 1 | XW21: 1 | AAH21: 2 | AAT21: 33
A22: 102335 | GL22: 1 | GV22: 1 | HA22: 1 | HT22: 2 | HV22: 1 | IE22: 1 | JA22: 1 | JI22: 1 | KN22: 1 | KP22: 1 | LA22: 1 | LB22: 1 | LN22: 1 | ME22: 1 | PA22: 1 | PN22: 1 | PT22: 1 | RF22: 1 | SC22: 1 | UA22: 1 | UQ22: 1 | UV22: 1 | VV22: 1 | WF22: 2 | WJ22: 1 | YX22: 1 | ZY22: 1 | AAT22: 29
A23: 102337 | BV23: 1 | GL23: 1 | GV23: 1 | HA23: 1 | HT23: 2 | HV23: 1 | JA23: 1 | JI23: 1 | KN23: 1 | KP23: 1 | LA23: 1 | LN23: 1 | ME23: 1 | PA23: 1 | PN23: 1 | RF23: 1 | SC23: 1 | UA23: 1 | UQ23: 1 | UV23: 1 | VV23: 1 | WF23: 2 | WJ23: 1 | YX23: 1 | ZY23: 1 | AAT23: 27
A24: 103817 | AE24: 1 | FS24: 1 | GI24: 1 | HA24: 1 | HT24: 1 | IQ24: 1 | IZ24: 1 | LU24: 1 | MC24: 1 | MM24: 1 | MS24: 1 | MW24: 1 | RC24: 1 | RM24: 1 | UA24: 1 | UU24: 1 | VG24: 1 | WC24: 1 | XL24: 1 | ZY24: 1 | AAF24: 1 | AAK24: 1 | AAM24: 1 | AAQ24: 1 | AAT24: 24
A25: 103860 | GI25: 1 | GV25: 2 | HV25: 1 | JA25: 1 | LJ25: 1 | LN25: 1 | LY25: 1 | RC25: 1 | RM25: 1 | TZ25: 1 | UQ25: 1 | VH25: 1 | WI25: 1 | WJ25: 1 | AAT25: 15
A26: 103981 | O26: 1 | AZ26: 1 | FM26: 1 | GI26: 1 | GV26: 1 | HA26: 1 | HT26: 3 | HV26: 1 | JA26: 1 | KP26: 1 | LN26: 1 | MD26: 1 | RE26: 1 | RT26: 1 | UA26: 1 | UQ26: 1 | UV26: 1 | VK26: 1 | WC26: 1 | WJ26: 1 | YX26: 1 | ZY26: 2 | AAF26: 1 | AAT26: 26
A27: 104124 | CB27: 1 | DV27: 1 | EV27: 1 | HT27: 2 | IH27: 1 | IK27: 1 | JA27: 1 | LU27: 1 | AAT27: 9
A28: 104359 | O28: 1 | Q28: 1 | ED28: 1 | FO28: 1 | GI28: 1 | GV28: 1 | HA28: 1 | HS28: 3 | HT28: 1 | HV28: 1 | IZ28: 1 | KM28: 1 | LG28: 1 | LZ28: 1 | PR28: 1 | RE28: 1 | RU28: 1 | UA28: 1 | UQ28: 1 | UV28: 1 | WC28: 1 | WJ28: 1 | YX28: 1 | YZ28: 1 | ZY28: 2 | ZZ28: 1 | AAG28: 1 | AAT28: 30
A29: 104424 | BJ29: 1 | CB29: 1 | GI29: 1 | GU29: 1 | HA29: 1 | HT29: 2 | HV29: 1 | JA29: 1 | PU29: 1 | UA29: 1 | UV29: 1 | XL29: 1 | YN29: 1 | YW29: 1 | ZU29: 1 | ZY29: 2 | AAN29: 1 | AAQ29: 1 | AAT29: 20
A30: 104425 | E30: 1 | BK30: 1 | GI30: 1 | GU30: 1 | HA30: 1 | HT30: 2 | HV30: 1 | JA30: 1 | PU30: 1 | UA30: 1 | UM30: 1 | UV30: 1 | WJ30: 1 | YN30: 1 | YW30: 1 | ZU30: 1 | ZY30: 2 | AAQ30: 1 | AAT30: 20
A31: 104562 | L31: 1 | O31: 1 | U31: 1 | AL31: 1 | BE31: 1 | CR31: 1 | GU31: 1 | HA31: 1 | HN31: 1 | HS31: 2 | HT31: 2 | HV31: 1 | LU31: 1 | QY31: 1 | RA31: 1 | UO31: 1 | UV31: 1 | WA31: 1 | WC31: 1 | WJ31: 1 | AAT31: 22
A32: 104567 | O32: 1 | Q32: 1 | ED32: 1 | FO32: 1 | GJ32: 1 | GU32: 1 | HA32: 1 | HS32: 3 | HT32: 1 | HV32: 1 | IZ32: 1 | KM32: 1 | LG32: 1 | LX32: 1 | NW32: 1 | RE32: 1 | RU32: 1 | UA32: 1 | UO32: 1 | UV32: 1 | WC32: 1 | WJ32: 1 | YW32: 1 | YZ32: 1 | ZY32: 2 | ZZ32: 1 | AAG32: 1 | AAK32: 1 | AAQ32: 1 | AAT32: 32
A33: 104672 | O33: 1 | AA33: 1 | CS33: 1 | GI33: 1 | GV33: 1 | HA33: 1 | HS33: 3 | HV33: 1 | KY33: 1 | LJ33: 1 | LN33: 1 | NE33: 1 | NL33: 1 | RE33: 1 | RT33: 1 | UA33: 1 | UQ33: 1 | UV33: 1 | UX33: 1 | WC33: 1 | WF33: 4 | WJ33: 1 | ZC33: 1 | ZQ33: 1 | AAT33: 29
A34: 104673 | EO34: 1 | ER34: 1 | GL34: 1 | GV34: 1 | HA34: 1 | HV34: 1 | JA34: 1 | MD34: 1 | RG34: 1 | SJ34: 1 | UD34: 1 | UQ34: 1 | UV34: 1 | WJ34: 1 | WU34: 1 | AAT34: 15
A35: 104713 | EK35: 1 | EO35: 1 | GV35: 1 | HV35: 1 | IB35: 1 | IW35: 1 | JA35: 1 | JE35: 1 | MB35: 1 | AAT35: 9
A36: 104715 | GI36: 1 | GU36: 1 | HA36: 1 | HV36: 1 | IN36: 1 | LJ36: 1 | LN36: 1 | NI36: 1 | PE36: 2 | UA36: 1 | UQ36: 1 | UV36: 1 | WG36: 3 | WJ36: 1 | XI36: 1 | XQ36: 1 | YJ36: 1 | YK36: 1 | YL36: 1 | ZO36: 1 | AAT36: 23
A37: 104718 | IH37: 1 | II37: 1 | IJ37: 1 | IQ37: 1 | KO37: 1 | LN37: 1 | MT37: 1 | AAT37: 7
A38: 104923 | DH38: 1 | HV38: 1 | JA38: 1 | JQ38: 1 | AAT38: 4
A39: 104963 | O39: 1 | BB39: 1 | GI39: 1 | GR39: 1 | HA39: 1 | HM39: 1 | HT39: 2 | AAT39: 8
A40: 105047 | EE40: 1 | EP40: 1 | FP40: 1 | GI40: 1 | GV40: 1 | HA40: 1 | HT40: 1 | HV40: 1 | JA40: 1 | LX40: 1 | PQ40: 1 | QM40: 1 | UA40: 1 | UQ40: 1 | UV40: 1 | WJ40: 1 | YV40: 1 | AAT40: 17
A41: 105121 | T41: 1 | DC41: 1 | ED41: 1 | GL41: 1 | GV41: 1 | HA41: 1 | HV41: 1 | IV41: 1 | IX41: 1 | JA41: 1 | KN41: 1 | LY41: 1 | AAT41: 12
A42: 105357 | ED42: 1 | GI42: 1 | GU42: 1 | HA42: 1 | HV42: 1 | JA42: 1 | LQ42: 1 | MC42: 1 | TI42: 1 | TX42: 1 | UO42: 1 | UV42: 1 | UZ42: 1 | WJ42: 1 | ZW42: 1 | ZY42: 1 | AAT42: 16
...

Sheet Binary
A1: Row Labels | B1: .122066KIT | C1: 1.00-SPADE-INS | D1: 1.00SPOTDRL | E1: 1.00SPOT-DRL-1 | F1: 1.750INS-DRL | G1: 1/16DRL | H1: 1/2-13-H3-PLG | I1: 1/2-13-SPLK-BTM-TAP | J1: 1/2-20-4FL-BTM | K1: 1/2-20-H11-BTM | L1: 1/2-2FL-CEM | M1: 1/2DRL | N1: 1/2FEROCIOUS-CEM | O1: 1/2SPOTDRL | P1: 1/4-20-2FL-H11-PLG | Q1: 1/4-20-SPLK-PLG-TAP | R1: 1/4-2FL-BALL-CEM | S1: 1/4-2FL-BALL-HSSEM | T1: 1/4-2FL-CEM | U1: 1/4DRL | V1: 1/4SPOTDRL | W1: 1/8-27-NPT-EXT | X1: 1/8-2FL-CEM | Y1: 1/8-DRL | Z1: 10-24-H11-PLG | AA1: 10-24-SPLK-2FL-PLG-TAP | AB1: 10-24-SPLK-BTM-TAP | AC1: 105691J | AD1: 10PITCHKNURL | AE1: 1-1/16BROACH | AF1: 11/16CBT-S+D-DRL | AG1: 11/16CLT-DRL-3/4SHK | AH1: 11/16DRL | AI1: 1-1/16DRL | AJ1: 11/16SMDRL | AK1: 1-1/16-SPADE-INS | AL1: 11/32CBD | AM1: 11/32DRL | AN1: 1-1/4-SPADE-INS | AO1: 1-1/8-SPADE-INS | AP1: 110078J | AQ1: 115232J | AR1: 117463-BOLT | AS1: 121907J | AT1: 122391J | AU1: 13/16BROACH | AV1: 13/16DRL | AW1: 1-3/16-SPADE-INS | AX1: 13/32CBD | AY1: 13/32DRL | AZ1: 13/64DRL | BA1: 15/32CBT-DRL | BB1: 17/64CBD | BC1: 18.00MM-SS-DRL | BD1: 19/32CBT-DRL | BE1: 19/32DRL | BF1: 2" BASE GROOVE BAR | BG1: 20PITCHKNURL | BH1: 22010S-100L-SPADE | BI1: 22020S-100L-SPADE | BJ1: 23/32CBT-DRL | BK1: 23/32SMDRL | BL1: 23010S-100L-SPADE | BM1: 23020S-125L-SPADE | BN1: 24010S-100L-SPADE | BO1: 25/64SMDRL | BP1: 29/64CBD | BQ1: 29/64SMDRL | BR1: 3.3MMDRL | BS1: 3/16-2FL-BALL-CEM | BT1: 3/16CBT-DRL | BU1: 3/16DRL | BV1: 3/16SPOTDRL | BW1: 3/4-16-H11-PLG | BX1: 3/4-2FL-CEM-TIN-COAT | BY1: 3/4-4FL-HSSEM | BZ1: 3/4DRL | CA1: 3/4-SPADE-INS | CB1: 3/4SPOTDRL | CC1: 3/8-16-EXT-H3-PLG | CD1: 3/8-16-EXT-SPLK-TAP | CE1: 3/8-16-SPLK-BTM-TAP | CF1: 3/8-24-H3-3FL-BTM | CG1: 3/8-2FL-BALL-CEM | CH1: 3/8-2FL-CEM | CI1: 3/8SPOTDRL | CJ1: 33/64-4FL-HSSEM | CK1: 33/64CBT-DRL | CL1: 33/64DRL | CM1: 33/64SMDRL | CN1: 35/64SMDRL | CO1: 37/64SMDRL | CP1: 4.00X.125-MLCTR | CQ1: 40007770J | CR1: 40075669J | CS1: 40081503J | CT1: 40084897J | CU1: 40085549J | CV1: 43/64TSDRL | CW1: 4303-C2F | CX1: 4-40-H11-PLG | CY1: 45/64SMDRL | CZ1: 5/16-24-H11-PLG | DA1: 5/16-2FL-CEM | DB1: 5/16DRL | DC1: 5/32DRL | DD1: 5/64-2FL-CEM | DE1: 5/64DRL | DF1: 5/8-18-4FL-BTM | DG1: 5/8-18-H11-PLG | DH1: 5/8-2FL-CEM | DI1: 5/8CLT-DRL | DJ1: 5/8DRL | DK1: 5/8SPOTDRL | DL1: 5973 | DM1: 6.4MM-CBT | DN1: 7/16-14-H3-4FL-BTM | DO1: 7/16CBT-DRL | DP1: 7/16DRL | DQ1: 7/32CBT-DRL | DR1: 7/8-SPADE-INS | DS1: 9/16-18-H11-BTM | DT1: 9/16-18-H11-PLG | DU1: 9/16-18-SPLK-BTM-TAP | DV1: 9/16CBTDRL | DW1: 9/16DRL | DX1: 9/32CBD | DY1: 9/32CBT-DRL | DZ1: A12NER2 | EA1: A12RA4EMR0307N | EB1: A12SCFPR3 | EC1: A16DCLNR4SS | ED1: A16NER3 | EE1: A16RA4EMR0410N | EF1: A16SDUCR3 | EG1: A16SVUBR3 | EH1: A20-DCLNR4 | EI1: A20MVUNR3 | EJ1: A20SA4EMR0412N | EK1: A24MDUNR4 | EL1: A24TA4EMR0416N | EM1: A32DCLNR | EN1: A3M50R326M | EO1: A4G0305M03U02GMN | EP1: A4G0405M04U04GMN | EQ1: A4G187I04P1GMN | ER1: A4M50R0314M | ES1: A4M50R0414M | ET1: A4R187I04P00GMN | EU1: ASSTLIVECENTERS | EV1: AT-10429L | EW1: AT-116A | EX1: B-1212 | EY1: B-3112-S | EZ1: BT-10939 | FA1: BT-11390 | FB1: BT-12340 | FC1: BT-12450 | FD1: BT-12723 | FE1: BT-13188 GAUGE | FF1: BT-1947-1 | FG1: BT-1947-2 | FH1: BT-1947-31 | FI1: BT-1947-8 | FJ1: BT-4301-6P-4T | FK1: BT-4302-11.5P-3T | FL1: BT-4302-11.5P-5T | FM1: BT-4303 | FN1: BT-4303-1 | FO1: BT-4303-7.5P-4T | FP1: BT-4303-7.5P-5T | FQ1: BT-4306-8P-7T | FR1: BT-4308 | FS1: BT-4309-9P-3T | FT1: BT-4309-9P-4T | FU1: BT-4314 | FV1: BT-4317-8P-5T | FW1: BT-5365 | FX1: BT-5365-11P-4T | FY1: BT-7203 | FZ1: C10SCLPR3-4 | GA1: C10SCLPR3-5 | GB1: C10SCLPR3-7 | GC1: C12SCLPR3-4 | GD1: C12SCLPR3-5 | GE1: C12SCLPR3-6 | GF1: C12SCLPR3-7 | GG1: C12SDUCR3 | GH1: C16-SCLPR3 | GI1: C16SCLPR3-4 | GJ1: C16SCLPR3-5 | GK1: C16SCLPR3-6 | GL1: C16SCLPR3-7 | GM1: C16SCLPR3X4 | GN1: C8SCLPR2-3 | GO1: C8SCLPR2-5 | GP1: CB3B | GQ1: CCGT4305HP | GR1: CHUCK-JAWKEYS | GS1: CNMG431 | GT1: CNMG432MLK10 | GU1: CNMG432MP-BRASS | GV1: CNMS432 | GW1: CNMS643 | GX1: CPMT2152LF | GY1: CPMT3250.5LF | GZ1: CPMT3251LF | HA1: CPMT3252LF | HB1: CPMT3252LF-CAP | HC1: CT-11397J | HD1: CT-12190-1J | HE1: CT-4811J | HF1: CT-5248-129 | HG1: CT-5248-132 | HH1: CT-5248-155 | HI1: CT-5248-164 | HJ1: CT-5248-19 | HK1: CT-6557-1J-NTX | HL1: CT-7346-3 | HM1: CT-8058J | HN1: DA-C08-500-LONG | HO1: DA-C16-1-INCH-LONG | HP1: DA-DT-12803 | HQ1: DA-E6-375-SHORT | HR1: DA-KGMSR-OD-A4 | HS1: DA-LIVE-X-HEAD | HT1: DA-LIVE-Z-HEAD | HU1: DA-TRIGON-POST | HV1: DCLNR164DKC | HW1: DDJNR164C | HX1: DGFH32-3 | HY1: DGNM-3202C | HZ1: DNMG432 | IA1: DNMS432 | IB1: DNMS432-K68 | IC1: DORTO1MS-10-HS | ID1: DPMT3252LF | IE1: DT-10170 | IF1: DT-10997J | IG1: DT-12375-HCJ | IH1: DT-12507 | II1: DT-12509 | IJ1: DT-12617 | IK1: DT-12848J | IL1: DT-12944 | IM1: DT-13047J | IN1: DT-13838-NTX | IO1: DT-13845-NTX | IP1: DT-13969 | IQ1: DVJNR163DKC3 | IR1: E16NER3 | IS1: E16SCLPR3 | IT1: E6SCLPR2 | IU1: EA-BOREBAR-EXT | IV1: EG125I03U05GUN | IW1: EVM50R0316MC | IX1: EVM50R0326MC | IY1: GFG188 | IZ1: HARD-JAWS-SMALL | JA1: HARD-JAWS-STD | JB1: ISCAR-SGTBU-CUTOFF | JC1: KBCR-CUTOFF | JD1: KEN1096448 | JE1: KGMSL165SN | JF1: KGMSR1650N | JG1: KIPR125XD-ENDMILL | JH1: KISR125LF | JI1: KM40-NRR3 | JJ1: K-TOOLSDCS901A1M | JK1: K-TOOLSDCS901L | JL1: K-TOOL-SDCS90-500 | JM1: K-TOOLSDCS90-500GR | JN1: K-TOOLSDCS90-750 | JO1: K-TOOLSDCS-90-750-A1M | JP1: LFEW-2521-FRLN | JQ1: LIVE-X | JR1: LIVE-Z | JS1: LSASR12 | JT1: LSASR163-LAYDN-THD | JU1: LT16ER18UN | JV1: LTR.H.CBD | JW1: LTR.P.DRL | JX1: LTR.Q.DRL | JY1: LTR.U.DRL | JZ1: M8X125-PLG-TAP | KA1: MAFORD-1-INCH-CHMF | KB1: MCHR-218-126 | KC1: MCHR-338-102 | KD1: MCHR-506-101-20 | KE1: MCHR-510-117-36 | KF1: MWLNR164C | KG1: N02886 | KH1: NG2125LK | KI1: NG3047R | KJ1: NG3062LK | KK1: NG3062RK | KL1: NG3094RK | KM1: NG3125L | KN1: NG3125LK | KO1: NG3125R | KP1: NG3125RK | KQ1: NG3189L | KR1: NG3189R | KS1: NO.02DRL | KT1: NO.03DRL | KU1: NO.04DRL | KV1: NO.09DRL | KW1: NO.11DRL | KX1: NO.20DRL | KY1: NO.21DRL | KZ1: NO.23DRL | LA1: NO.24DRL | LB1: NO.2CD6 | LC1: NO.30CBT-DRL | LD1: NO.30EXL-DRL | LE1: NO.41DRL | LF1: NO.46DRL | LG1: NO.4CBT-DRL | LH1: NR3031R | LI1: NR3062L | LJ1: NR3062R | LK1: NR4062L | LL1: NR4125L | LM1: NSL163C | LN1: NSR163C | LO1: NSR164C | LP1: NT2L | LQ1: NT3L | LR1: NT3R | LS1: NTP3R | LT1: NWC-3L11I | LU1: SOLID-ID-BLOCK | LV1: SPMX-1504AP-75 | LW1: SSO75ER16700 | LX1: STOPBLOCK100 | LY1: STOPBLOCK1125 | LZ1: STOPBLOCK1250 | MA1: STOPBLOCK1375 | MB1: STOPBLOCK1500 | MC1: STOPBLOCK1625 | MD1: STOPBLOCK1750 | ME1: STOPBLOCK500 | MF1: STOPBLOCK750 | MG1: SUPERSTUBBY2A24 | MH1: T-404-CONICAL-E-MILL | MI1: TAE-2830078 | MJ1: TDJ4-15L | MK1: TF25423A3 | ML1: TPG432 | MM1: TRIGON-OD-TURN | MN1: VAL100XTN | MO1: VAL750XTN | MP1: VNGP330.5 | MQ1: VNMG332 | MR1: VNMG332MP | MS1: VNMG432 | MT1: VNMS332 | MU1: VNMS-332 | MV1: WCMX080412-85 | MW1: WNMG432MP | MX1: WNMG432MP KC 5010 | MY1: X6030000X012080 | MZ1: XDMT2322R | NA1: 0087374J | NB1: 1/2-13-H3-PLG | NC1: 1/2-2FL-CEM | ND1: 1/2-2FL-EXL-CEM | NE1: 1/2SPOTDRL | NF1: 1/4-20 H10 FORM TAP | NG1: 1/4-20-GH11-DRAP | NH1: 1/4-20-H11-BTM-OSG | NI1: 1/4-20-H11-EXT-PLG-TAP | NJ1: 1/4-20-H3-2FL-PLG | NK1: 1/4-20-H3-BTM | NL1: 1/4-20-SPLK-PLG-TAP | NM1: 1/4SPOTDRL | NN1: 101944 | NO1: 102067 | NP1: 102084L | NQ1: 10-24 H10 FORM TAP | NR1: 10-24-EXT-H3-PLG | NS1: 10-24-H11-4FL-BTM | NT1: 10-24-H11-PLG | NU1: 10-24-H3-2FL-PLG | NV1: 10-24-SPLK-2FL-PLG-TAP | NW1: 104576L | NX1: 105691J | NY1: 105990L | NZ1: 106859J | OA1: 108033L | OB1: 108166-RING | OC1: 109477GB | OD1: 11/16SMDRL | OE1: 11/32-2FL-CEM | OF1: 110171J | OG1: 115606 | OH1: 115987L | OI1: 117077 | OJ1: 117605L | OK1: 117901-NTX | OL1: 117946-NTX | OM1: 118764J | ON1: 122104J | OO1: 122391-2 | OP1: 122391J | OQ1: 124357L-NTX | OR1: 126160-2L-NTX | OS1: 126532 | OT1: 127160L | OU1: 127720L-NTX | OV1: 13/64DRL | OW1: 15/32CBD | OX1: 17/32CBD | OY1: 2.60MM-OSG | OZ1: 23/32SMDRL | PA1: 3/16-2FL-CEM | PB1: 3/16-2FL-DE-BALL-HSSEM | PC1: 3/16CBT-DRL | PD1: 3/4-2FL-CEM-TIN-COAT | PE1: 3/4SPOTDRL | PF1: 3/8-16-EXT-H11-PLG | PG1: 3/8-16-EXT-H3-BTM | PH1: 3/8-16-EXT-H3-PLG | PI1: 3/8-16-EXT-SPLK-TAP | PJ1: 3/8-16-H11-PLG | PK1: 3/8-16-H3-3FL-BTM | PL1: 3/8-16-H3-PLG | PM1: 3/8-24-H11-2FL-BTM | PN1: 3/8-2FL-CEM | PO1: 3/8SPOTDRL | PP1: 37/64DRL | PQ1: 40010182J | PR1: 40011107L | PS1: 40022400J | PT1: 40058853J | PU1: 40059798J | PV1: 40086213J-NTX | PW1: 5/16CBT-DRL | PX1: 5/16DRL | PY1: 5/16SMDRL | PZ1: 5/8-11-H11-PLG | QA1: 5/8-18-H3-EXT | QB1: 6.4MMDRL | QC1: 6-32-H11-3FL-PLG | QD1: 6-32-H11-PLG | QE1: 6-32-H3-3FL-PLG | QF1: 6-32-H3-PLG | QG1: 7/16DRL | QH1: 7/32-2FL-CEM | QI1: 8-32-H11-PLG | QJ1: A10NER2-SHORT | QK1: A12NER2 | QL1: A16DCLNR4SS | QM1: A16NER3 | QN1: A24MDUNR4 | QO1: A24TA4EMR0416N | QP1: A24TA4EMRO416N | QQ1: A4-1.250-GROOVE | QR1: A4G0305M03U02GMN | QS1: A4G0405M04U04GMN | QT1: A4G0405M04U08GMN | QU1: A4M50R0414M | QV1: A4R187I04P00GMN | QW1: A8NER2 | QX1: AC102 | QY1: AC203 | QZ1: AC2110 | RA1: AC2210 | RB1: AC2410 | RC1: AC2510 | RD1: AC2610 | RE1: AC2710 | RF1: AC2810 | RG1: AC2910 | RH1: AC401 | RI1: AC403 | RJ1: AC409 | RK1: AC501 | RL1: AC505 | RM1: AC509 | RN1: AC513 | RO1: AC602 | RP1: AC606 | RQ1: AC610 | RR1: AC614 | RS1: AC615 | RT1: AC703 | RU1: AC715 | RV1: AC716 | RW1: AC718 | RX1: AC719 | RY1: AC720 | RZ1: AC721 | SA1: AC726 | SB1: AC727 | SC1: AC803 | SD1: AC813 | SE1: AC815 | SF1: AC901 | SG1: AC907 | SH1: AC908 | SI1: AC911 | SJ1: AC913 | SK1: AC915 | SL1: AC923 | SM1: AC924 | SN1: AC927 | SO1: AC928 | SP1: AC929 | SQ1: AC931 | SR1: ADKT16221 | SS1: BT-10251 | ST1: BT-10939 | SU1: BT-11376 | SV1: BT-11390 | SW1: BT-11417 | SX1: BT-12340 | SY1: BT-12450 | SZ1: BT-12678 | TA1: BT-12683 | TB1: BT-13022L-NTX | TC1: BT-1947 | TD1: BT-1947-1 | TE1: BT-1947-2 | TF1: BT-1947-9 | TG1: BT-3208-2 | TH1: BT-3890-1 | TI1: BT-3974 | TJ1: BT-4302-11.5P-5T | TK1: BT-4303-7.5P-4T | TL1: BT-4303-7.5P-5T | TM1: BT-4308-8P-3T | TN1: BT-4314 | TO1: BT-5365-11P-4T | TP1: BT-5722-12 | TQ1: BT-7203 | TR1: BT-7315L | TS1: BT-8767 | TT1: BT-8837 | TU1: C10SCLPR2-4 | TV1: C10SCLPR3-4 | TW1: C10SCLPR3-5 | TX1: C12SCLPR3-4 | TY1: C12SCLPR3-7 | TZ1: C12SDUCR3 | UA1: C16SCLPR3-4 | UB1: C16SCLPR3-5 | UC1: C16SCLPR3-6 | UD1: C16SCLPR3-7 | UE1: C16SCLPR3X4 | UF1: C6SCLPR2 | UG1: C8SCLPR2 | UH1: C8SCLPR2-3 | UI1: C8SCLPR2-4 | UJ1: C8SCLPR2-5 | UK1: C8SCLPR3-4 | UL1: CNGP432-ALUM | UM1: CNMG432MF | UN1: CNMG432MLK10 | UO1: CNMG432MP-BRASS | UP1: CNMG434RP | UQ1: CNMS432 | UR1: CPGT3252HP | US1: CPMT2151LF | UT1: CPMT2152LF | UU1: CPMT3251LF | UV1: CPMT3252LF | UW1: CPMT3252LF-CAP | UX1: CT-11160 | UY1: CT-11375 | UZ1: CT-11409 | VA1: CT-11418 | VB1: CT-11549-20 | VC1: CT-11849 | VD1: CT-5248-130 | VE1: CT-5248-85 | VF1: CT-5533L | VG1: CT-6002-1 | VH1: CT-6002-21 | VI1: CT-6003-10 | VJ1: CT-6003-7 | VK1: CT-6004-10 | VL1: CT-6004-12 | VM1: CT-6004-21 | VN1: CT-6004-24 | VO1: CT-6004-29 | VP1: CT-6004-31 | VQ1: CT-6004-34 | VR1: CT-6005-12 | VS1: CT-6005-13 | VT1: CT-6005-4-NTX | VU1: CT-6006-4 | VV1: CT-6006-7 | VW1: CT-6545-2 | VX1: CT-7517-1 | VY1: CT-7961-NTX | VZ1: CT-8904 | WA1: DA-C08-500-SHORT | WB1: DA-C16-1-INCH-LONG | WC1: DA-DT-12803 | WD1: DA-E6-375-SHORT | WE1: DA-KGMSR-OD-A4 | WF1: DA-LIVE-X-HEAD | WG1: DA-LIVE-Z-HEAD | WH1: DA-TRIGON-POST | WI1: DCGX-3252AL | WJ1: DCLNR164DKC | WK1: DDJNR164C | WL1: DGFH32-3 | WM1: DGNM-3202C | WN1: DNMG432 | WO1: DNMS432 | WP1: DT-10236-1 | WQ1: DT-11628 | WR1: DT-11628-XL | WS1: DT-12104 | WT1: DT-12260 | WU1: DT-12458 | WV1: DT-12693 | WW1: DT-12896L-NTX | WX1: DT-12983 | WY1: DT-13019L | WZ1: DT-13171-1 | XA1: DT-13171-2 | XB1: DT-13194 | XC1: DT-13216 | XD1: DT-13531 | XE1: DT-13532 | XF1: DT-13534-NTX | XG1: DT-13589-NTX | XH1: DT-13845-NTX | XI1: DT-13915-NTX | XJ1: DT-14021 | XK1: DVJNL163C | XL1: DVJNR163DKC3 | XM1: ER125I03P00GUP | XN1: EVM50R0312MC | XO1: EVM50R0316MC | XP1: EVM50R0326MC | XQ1: GFG125CC | XR1: HARD-JAWS-STD | XS1: ISCAR FACE GROOVE INSERT | XT1: ISCAR INT FACE GROOVE BLADE #8 | XU1: ISCAR INT RH FACE GROOVE BAR | XV1: ISCAR-SGTBU-CUTOFF | XW1: KGMSL165SN | XX1: KGMSR1650N | XY1: KISR100AD | XZ1: KISR125LF | YA1: K-TOOLSDCS901A1M | YB1: K-TOOL-SDCS90-500 | YC1: K-TOOLSDCS90-500GR | YD1: LFEW-2521-FRLN | YE1: LIVE-X | YF1: LIVE-Z | YG1: LTR.O.DRL | YH1: LTR.P.DRL | YI1: MCHR-218-121 | YJ1: MCHR-235-101 | YK1: MCHR-338-101 | YL1: MCHR-440-101 | YM1: MCHR-510-117-36 | YN1: MWLNR164C | YO1: NG2094LK | YP1: NG2125LK | YQ1: NG3062LK | YR1: NG3062R | YS1: NG3094LK KC5010 | YT1: NG3094R | YU1: NG3125L | YV1: NG3125LK | YW1: NG3125R | YX1: NG3125RK | YY1: NG3189R | YZ1: NG4250R | ZA1: NO.01DRL | ZB1: NO.07DRL | ZC1: NO.10DRL | ZD1: NO.18DRL | ZE1: NO.21DRL | ZF1: NO.23DRL | ZG1: NO.25DRL | ZH1: NO.25EXL-DRL | ZI1: NO.28DRL | ZJ1: NO.30CBT-DRL | ZK1: NO.33DRL | ZL1: NO.34DRL | ZM1: NO.35DRL | ZN1: NO.36DRL | ZO1: NO.4 CBT | ZP1: NO.41DRL | ZQ1: NO.4CBT-DRL | ZR1: NO.5CD2 | ZS1: NO.7CBD | ZT1: NO.7SMDRL | ZU1: NR3031R | ZV1: NR3062L | ZW1: NR3062R | ZX1: NSL163C | ZY1: NSR163C | ZZ1: NSR164C | AAA1: NT2L | AAB1: NT3L | AAC1: NT3R | AAD1: NTP2L | AAE1: NTP3L | AAF1: NTP3R | AAG1: NWC-3R11E | AAH1: SOLID-ID-BLOCK | AAI1: STOPBLOCK1250 | AAJ1: SUPERSTUBBY2A12 | AAK1: TRIGON-OD-TURN | AAL1: VNGP330.5 | AAM1: VNMG332 | AAN1: VNMG332MP | AAO1: VNMS332 | AAP1: VNMS-332 | AAQ1: WNMG432MP | AAR1: .500-1/2-CBORE | AAS1: 5/32EXL-DRL
A2: 03300003 | B2: =IF(Pivot!B6>0,1,0) -> 0 | C2: =IF(Pivot!C6>0,1,0) -> 0 | D2: =IF(Pivot!D6>0,1,0) -> 0 | E2: =IF(Pivot!E6>0,1,0) -> 0 | F2: =IF(Pivot!F6>0,1,0) -> 0 | G2: =IF(Pivot!G6>0,1,0) -> 0 | H2: =IF(Pivot!H6>0,1,0) -> 0 | I2: =IF(Pivot!I6>0,1,0) -> 0 | ... AAS2: =IF(Pivot!AAS6>0,1,0) -> 0
A3: 03300005 | B3: =IF(Pivot!B7>0,1,0) -> 0 | C3: =IF(Pivot!C7>0,1,0) -> 0 | D3: =IF(Pivot!D7>0,1,0) -> 0 | E3: =IF(Pivot!E7>0,1,0) -> 0 | F3: =IF(Pivot!F7>0,1,0) -> 0 | G3: =IF(Pivot!G7>0,1,0) -> 0 | H3: =IF(Pivot!H7>0,1,0) -> 0 | I3: =IF(Pivot!I7>0,1,0) -> 0 | ... AAS3: =IF(Pivot!AAS7>0,1,0) -> 0
A4: 03360009 | B4: =IF(Pivot!B8>0,1,0) -> 0 | C4: =IF(Pivot!C8>0,1,0) -> 0 | D4: =IF(Pivot!D8>0,1,0) -> 0 | E4: =IF(Pivot!E8>0,1,0) -> 0 | F4: =IF(Pivot!F8>0,1,0) -> 0 | G4: =IF(Pivot!G8>0,1,0) -> 0 | H4: =IF(Pivot!H8>0,1,0) -> 0 | I4: =IF(Pivot!I8>0,1,0) -> 0 | ... AAS4: =IF(Pivot!AAS8>0,1,0) -> 0
A5: 100217 | B5: =IF(Pivot!B9>0,1,0) -> 0 | C5: =IF(Pivot!C9>0,1,0) -> 0 | D5: =IF(Pivot!D9>0,1,0) -> 0 | E5: =IF(Pivot!E9>0,1,0) -> 0 | F5: =IF(Pivot!F9>0,1,0) -> 0 | G5: =IF(Pivot!G9>0,1,0) -> 0 | H5: =IF(Pivot!H9>0,1,0) -> 0 | I5: =IF(Pivot!I9>0,1,0) -> 0 | ... AAS5: =IF(Pivot!AAS9>0,1,0) -> 0
A6: 100728 | B6: =IF(Pivot!B10>0,1,0) -> 0 | C6: =IF(Pivot!C10>0,1,0) -> 0 | D6: =IF(Pivot!D10>0,1,0) -> 0 | E6: =IF(Pivot!E10>0,1,0) -> 0 | F6: =IF(Pivot!F10>0,1,0) -> 0 | G6: =IF(Pivot!G10>0,1,0) -> 0 | H6: =IF(Pivot!H10>0,1,0) -> 0 | I6: =IF(Pivot!I10>0,1,0) -> 0 | ... AAS6: =IF(Pivot!AAS10>0,1,0) -> 0
A7: 100733 | B7: =IF(Pivot!B11>0,1,0) -> 0 | C7: =IF(Pivot!C11>0,1,0) -> 0 | D7: =IF(Pivot!D11>0,1,0) -> 0 | E7: =IF(Pivot!E11>0,1,0) -> 0 | F7: =IF(Pivot!F11>0,1,0) -> 0 | G7: =IF(Pivot!G11>0,1,0) -> 0 | H7: =IF(Pivot!H11>0,1,0) -> 0 | I7: =IF(Pivot!I11>0,1,0) -> 0 | ... AAS7: =IF(Pivot!AAS11>0,1,0) -> 0
A8: 100735 | B8: =IF(Pivot!B12>0,1,0) -> 0 | C8: =IF(Pivot!C12>0,1,0) -> 0 | D8: =IF(Pivot!D12>0,1,0) -> 0 | E8: =IF(Pivot!E12>0,1,0) -> 0 | F8: =IF(Pivot!F12>0,1,0) -> 0 | G8: =IF(Pivot!G12>0,1,0) -> 0 | H8: =IF(Pivot!H12>0,1,0) -> 0 | I8: =IF(Pivot!I12>0,1,0) -> 0 | ... AAS8: =IF(Pivot!AAS12>0,1,0) -> 0
A9: 100743 | B9: =IF(Pivot!B13>0,1,0) -> 0 | C9: =IF(Pivot!C13>0,1,0) -> 0 | D9: =IF(Pivot!D13>0,1,0) -> 0 | E9: =IF(Pivot!E13>0,1,0) -> 0 | F9: =IF(Pivot!F13>0,1,0) -> 0 | G9: =IF(Pivot!G13>0,1,0) -> 0 | H9: =IF(Pivot!H13>0,1,0) -> 0 | I9: =IF(Pivot!I13>0,1,0) -> 0 | ... AAS9: =IF(Pivot!AAS13>0,1,0) -> 0
A10: 100746 | B10: =IF(Pivot!B14>0,1,0) -> 0 | C10: =IF(Pivot!C14>0,1,0) -> 0 | D10: =IF(Pivot!D14>0,1,0) -> 0 | E10: =IF(Pivot!E14>0,1,0) -> 0 | F10: =IF(Pivot!F14>0,1,0) -> 0 | G10: =IF(Pivot!G14>0,1,0) -> 0 | H10: =IF(Pivot!H14>0,1,0) -> 0 | I10: =IF(Pivot!I14>0,1,0) -> 0 | ... AAS10: =IF(Pivot!AAS14>0,1,0) -> 0
A11: 101944 | B11: =IF(Pivot!B15>0,1,0) -> 0 | C11: =IF(Pivot!C15>0,1,0) -> 0 | D11: =IF(Pivot!D15>0,1,0) -> 0 | E11: =IF(Pivot!E15>0,1,0) -> 0 | F11: =IF(Pivot!F15>0,1,0) -> 0 | G11: =IF(Pivot!G15>0,1,0) -> 0 | H11: =IF(Pivot!H15>0,1,0) -> 0 | I11: =IF(Pivot!I15>0,1,0) -> 0 | ... AAS11: =IF(Pivot!AAS15>0,1,0) -> 0
A12: 102067 | B12: =IF(Pivot!B16>0,1,0) -> 0 | C12: =IF(Pivot!C16>0,1,0) -> 0 | D12: =IF(Pivot!D16>0,1,0) -> 0 | E12: =IF(Pivot!E16>0,1,0) -> 0 | F12: =IF(Pivot!F16>0,1,0) -> 0 | G12: =IF(Pivot!G16>0,1,0) -> 0 | H12: =IF(Pivot!H16>0,1,0) -> 0 | I12: =IF(Pivot!I16>0,1,0) -> 0 | ... AAS12: =IF(Pivot!AAS16>0,1,0) -> 0
A13: 102084 | B13: =IF(Pivot!B17>0,1,0) -> 0 | C13: =IF(Pivot!C17>0,1,0) -> 0 | D13: =IF(Pivot!D17>0,1,0) -> 0 | E13: =IF(Pivot!E17>0,1,0) -> 0 | F13: =IF(Pivot!F17>0,1,0) -> 0 | G13: =IF(Pivot!G17>0,1,0) -> 0 | H13: =IF(Pivot!H17>0,1,0) -> 0 | I13: =IF(Pivot!I17>0,1,0) -> 0 | ... AAS13: =IF(Pivot!AAS17>0,1,0) -> 0
... A203: 3300003 | B203: =IF(Pivot!B207>0,1,0) -> 0 | C203: =IF(Pivot!C207>0,1,0) -> 0 | D203: =IF(Pivot!D207>0,1,0) -> 0 | E203: =IF(Pivot!E207>0,1,0) -> 0 | F203: =IF(Pivot!F207>0,1,0) -> 0 | G203: =IF(Pivot!G207>0,1,0) -> 0 | H203: =IF(Pivot!H207>0,1,0) -> 0 | I203: =IF(Pivot!I207>0,1,0) -> 0 | ... AAS203: =IF(Pivot!AAS207>0,1,0) -> 0

Sheet Tool_Matrix
A1: Lables | B1: 03300003 | C1: 03300005 | D1: 03360009 | E1: 100217 | F1: 100728 | G1: 100733 | H1: 100735 | I1: 100743 | J1: 100746 | K1: 101944 | L1: 102067 | M1: 102084 | N1: 102091 | O1: 102091C | P1: 102149 | Q1: 102314 | R1: 102335 | S1: 102337 | T1: 103817 | U1: 103860 | V1: 103981 | W1: 104124 | X1: 104359 | Y1: 104424 | Z1: 104425 | AA1: 104562 | AB1: 104567 | AC1: 104672 | AD1: 104673 | AE1: 104713 | AF1: 104715 | AG1: 104718 | AH1: 104923 | AI1: 104963 | AJ1: 105047 | AK1: 105121 | AL1: 105357 | AM1: 105397 | AN1: 105602 | AO1: 105691 | AP1: 105726a | AQ1: 105990 | AR1: 105991 | AS1: 106200 | AT1: 106200A | AU1: 106859 | AV1: 107090 | AW1: 107553 | AX1: 107863 | AY1: 107873 | AZ1: 107874 | BA1: 107901 | BB1: 107980 | BC1: 108010 | BD1: 108033 | BE1: 108037 | BF1: 108058 | BG1: 108068 | BH1: 108076 | BI1: 108079 | BJ1: 108166 | BK1: 108198 | BL1: 108288 | BM1: 108327 | BN1: 108333 | BO1: 108349 | BP1: 108987 | BQ1: 109449 | BR1: 109452 | BS1: 109680 | BT1: 109865 | BU1: 109873 | BV1: 110185 | BW1: 115181B | BX1: 115232 | BY1: 115397 | BZ1: 115598 | CA1: 115606 | CB1: 115612 | CC1: 115733 | CD1: 115987 | CE1: 116015 | CF1: 116308 | CG1: 116326 | CH1: 116372 | CI1: 116373 | CJ1: 116509 | CK1: 116510 | CL1: 116593 | CM1: 116730 | CN1: 116807 | CO1: 117077A | CP1: 117162 | CQ1: 117463 | CR1: 117651 | CS1: 117666 | CT1: 117728 | CU1: 117901 | CV1: 117946a | CW1: 118160 | CX1: 118476A | CY1: 118490 | CZ1: 118496 | DA1: 118536 | DB1: 118703 | DC1: 118874 | DD1: 118962 | DE1: 119010 | DF1: 119016 | DG1: 119127 | DH1: 119886 | DI1: 120040 | DJ1: 120093 | DK1: 120260A | DL1: 120268 | DM1: 120309A | DN1: 120414 | DO1: 120445 | DP1: 120455 | DQ1: 120779 | DR1: 121117 | DS1: 121126 | DT1: 121201 | DU1: 121272 | DV1: 121278 | DW1: 121279 | DX1: 121358 | DY1: 121363 | DZ1: 121374 | EA1: 121581 | EB1: 121594 | EC1: 121638 | ED1: 121710 | EE1: 121872 | EF1: 121880 | EG1: 121907 | EH1: 121961 | EI1: 122031 | EJ1: 122066 | EK1: 122104 | EL1: 122215 | EM1: 122377 | EN1: 122390 | EO1: 122391 | EP1: 122396 | EQ1: 122442 | ER1: 122464 | ES1: 122766 | ET1: 122803 | EU1: 122915 | EV1: 122976 | EW1: 123015 | EX1: 123051 | EY1: 123073 | EZ1: 123189 | FA1: 123202 | FB1: 123239 | FC1: 123240 | FD1: 123241 | FE1: 123285 | FF1: 123424 | FG1: 123430 | FH1: 123520 | FI1: 123566 | FJ1: 123583 | FK1: 124144 | FL1: 124471 | FM1: 124551 | FN1: 124758 | FO1: 124759 | FP1: 124776 | FQ1: 124778 | FR1: 125870 | FS1: 125871 | FT1: 125873 | FU1: 125874 | FV1: 126160 | FW1: 126219 | FX1: 126249 | FY1: 126340 | FZ1: 126532 | GA1: 126981 | GB1: 127160 | GC1: 127324 | GD1: 127324A | GE1: 127397 | GF1: 127403 | GG1: 127450 | GH1: 127666 | GI1: 127708 | GJ1: 127720a | GK1: 127721A | GL1: 127722A | GM1: 127723a | GN1: 127729 | GO1: 127854 | GP1: 127864 | GQ1: 127868a | GR1: 127869A | GS1: 127870A | GT1: 128626 | GU1: 3300003
A2: 03300003 | B2: 15 | C2: 15 | D2: 4 | E2: 4 | F2: 4 | G2: 4 | H2: 4 | I2: 4 | J2: 3 | K2: 3 | L2: 3 | M2: 3 | N2: 4 | O2: 4 | P2: 6 | Q2: 3 | R2: 4 | S2: 4 | T2: 7 | U2: 3 | V2: 6 | W2: 1 | X2: 5 | Y2: 7 | Z2: 6 | AA2: 3 | AB2: 5 | AC2: 3 | AD2: 3 | AE2: 2 | AF2: 4 | AG2: 0 | AH2: 2 | AI2: 2 | AJ2: 4 | AK2: 4 | AL2: 11 | AM2: 3 | AN2: 6 | AO2: 4 | AP2: 3 | AQ2: 1 | AR2: 3 | AS2: 5 | AT2: 5 | AU2: 3 | AV2: 3 | AW2: 1 | AX2: 4 | AY2: 4 | AZ2: 4 | BA2: 2 | BB2: 3 | BC2: 5 | BD2: 6 | BE2: 6 | BF2: 3 | BG2: 3 | BH2: 5 | BI2: 4 | BJ2: 9 | BK2: 4 | BL2: 4 | BM2: 3 | BN2: 4 | BO2: 3 | BP2: 4 | BQ2: 5 | BR2: 6 | BS2: 3 | BT2: 0 | BU2: 0 | BV2: 5 | BW2: 4 | BX2: 5 | BY2: 3 | BZ2: 3 | CA2: 3 | CB2: 3 | CC2: 6 | CD2: 7 | CE2: 2 | CF2: 3 | CG2: 4 | CH2: 4 | CI2: 3 | CJ2: 3 | CK2: 3 | CL2: 6 | CM2: 5 | CN2: 6 | CO2: 3 | CP2: 3 | CQ2: 2 | CR2: 3 | CS2: 8 | CT2: 1 | CU2: 2 | CV2: 4 | CW2: 6 | CX2: 4 | CY2: 7 | CZ2: 3 | DA2: 1 | DB2: 2 | DC2: 3 | DD2: 4 | DE2: 4 | DF2: 4 | DG2: 3 | DH2: 3 | DI2: 3 | DJ2: 3 | DK2: 4 | DL2: 6 | DM2: 3 | DN2: 6 | DO2: 4 | DP2: 4 | DQ2: 5 | DR2: 4 | DS2: 4 | DT2: 5 | DU2: 4 | DV2: 4 | DW2: 4 | DX2: 3 | DY2: 3 | DZ2: 3 | EA2: 4 | EB2: 3 | EC2: 6 | ED2: 5 | EE2: 1 | EF2: 3 | EG2: 4 | EH2: 1 | EI2: 3 | EJ2: 3 | EK2: 3 | EL2: 8 | EM2: 2 | EN2: 3 | EO2: 4 | EP2: 3 | EQ2: 6 | ER2: 2 | ES2: 3 | ET2: 6 | EU2: 5 | EV2: 8 | EW2: 2 | EX2: 2 | EY2: 1 | EZ2: 4 | FA2: 4 | FB2: 3 | FC2: 3 | FD2: 3 | FE2: 3 | FF2: 1 | FG2: 4 | FH2: 3 | FI2: 3 | FJ2: 3 | FK2: 4 | FL2: 4 | FM2: 3 | FN2: 3 | FO2: 3 | FP2: 3 | FQ2: 3 | FR2: 3 | FS2: 4 | FT2: 4 | FU2: 3 | FV2: 3 | FW2: 4 | FX2: 5 | FY2: 6 | FZ2: 4 | GA2: 3 | GB2: 4 | GC2: 3 | GD2: 3 | GE2: 4 | GF2: 7 | GG2: 6 | GH2: 4 | GI2: 6 | GJ2: 3 | GK2: 3 | GL2: 3 | GM2: 4 | GN2: 3 | GO2: 3 | GP2: 3 | GQ2: 3 | GR2: 3 | GS2: 3 | GT2: 2 | GU2: 10
A3: 03300005 | B3: 15 | C3: 15 | D3: 4 | E3: 4 | F3: 4 | G3: 4 | H3: 4 | I3: 4 | J3: 3 | K3: 3 | L3: 3 | M3: 3 | N3: 4 | O3: 4 | P3: 6 | Q3: 3 | R3: 4 | S3: 4 | T3: 7 | U3: 3 | V3: 6 | W3: 1 | X3: 5 | Y3: 7 | Z3: 6 | AA3: 3 | AB3: 5 | AC3: 3 | AD3: 3 | AE3: 2 | AF3: 4 | AG3: 0 | AH3: 2 | AI3: 2 | AJ3: 4 | AK3: 4 | AL3: 11 | AM3: 3 | AN3: 6 | AO3: 4 | AP3: 3 | AQ3: 1 | AR3: 3 | AS3: 5 | AT3: 5 | AU3: 3 | AV3: 3 | AW3: 1 | AX3: 4 | AY3: 4 | AZ3: 4 | BA3: 2 | BB3: 3 | BC3: 5 | BD3: 6 | BE3: 6 | BF3: 3 | BG3: 3 | BH3: 5 | BI3: 4 | BJ3: 9 | BK3: 4 | BL3: 4 | BM3: 3 | BN3: 4 | BO3: 3 | BP3: 4 | BQ3: 5 | BR3: 6 | BS3: 3 | BT3: 0 | BU3: 0 | BV3: 5 | BW3: 4 | BX3: 5 | BY3: 3 | BZ3: 3 | CA3: 3 | CB3: 3 | CC3: 6 | CD3: 7 | CE3: 2 | CF3: 3 | CG3: 4 | CH3: 4 | CI3: 3 | CJ3: 3 | CK3: 3 | CL3: 6 | CM3: 5 | CN3: 6 | CO3: 3 | CP3: 3 | CQ3: 2 | CR3: 3 | CS3: 8 | CT3: 1 | CU3: 2 | CV3: 4 | CW3: 6 | CX3: 4 | CY3: 7 | CZ3: 3 | DA3: 1 | DB3: 2 | DC3: 3 | DD3: 4 | DE3: 4 | DF3: 4 | DG3: 3 | DH3: 3 | DI3: 3 | DJ3: 3 | DK3: 4 | DL3: 6 | DM3: 3 | DN3: 6 | DO3: 4 | DP3: 4 | DQ3: 5 | DR3: 4 | DS3: 4 | DT3: 5 | DU3: 4 | DV3: 4 | DW3: 4 | DX3: 3 | DY3: 3 | DZ3: 3 | EA3: 4 | EB3: 3 | EC3: 6 | ED3: 5 | EE3: 1 | EF3: 3 | EG3: 4 | EH3: 1 | EI3: 3 | EJ3: 3 | EK3: 3 | EL3: 8 | EM3: 2 | EN3: 3 | EO3: 4 | EP3: 3 | EQ3: 6 | ER3: 2 | ES3: 3 | ET3: 6 | EU3: 5 | EV3: 8 | EW3: 2 | EX3: 2 | EY3: 1 | EZ3: 4 | FA3: 4 | FB3: 3 | FC3: 3 | FD3: 3 | FE3: 3 | FF3: 1 | FG3: 4 | FH3: 3 | FI3: 3 | FJ3: 3 | FK3: 4 | FL3: 4 | FM3: 3 | FN3: 3 | FO3: 3 | FP3: 3 | FQ3: 3 | FR3: 3 | FS3: 4 | FT3: 4 | FU3: 3 | FV3: 3 | FW3: 4 | FX3: 5 | FY3: 6 | FZ3: 4 | GA3: 3 | GB3: 4 | GC3: 3 | GD3: 3 | GE3: 4 | GF3: 7 | GG3: 6 | GH3: 4 | GI3: 6 | GJ3: 3 | GK3: 3 | GL3: 3 | GM3: 4 | GN3: 3 | GO3: 3 | GP3: 3 | GQ3: 3 | GR3: 3 | GS3: 3 | GT3: 2 | GU3: 10
A4: 03360009 | B4: 4 | C4: 4 | D4: 26 | E4: 12 | F4: 5 | G4: 5 | H4: 5 | I4: 5 | J4: 4 | K4: 6 | L4: 6 | M4: 8 | N4: 5 | O4: 6 | P4: 11 | Q4: 10 | R4: 13 | S4: 13 | T4: 9 | U4: 6 | V4: 15 | W4: 2 | X4: 12 | Y4: 8 | Z4: 9 | AA4: 6 | AB4: 13 | AC4: 10 | AD4: 7 | AE4: 3 | AF4: 8 | AG4: 1 | AH4: 2 | AI4: 2 | AJ4: 11 | AK4: 4 | AL4: 6 | AM4: 5 | AN4: 6 | AO4: 4 | AP4: 5 | AQ4: 6 | AR4: 6 | AS4: 6 | AT4: 6 | AU4: 12 | AV4: 5 | AW4: 2 | AX4: 11 | AY4: 9 | AZ4: 9 | BA4: 2 | BB4: 11 | BC4: 4 | BD4: 13 | BE4: 11 | BF4: 9 | BG4: 10 | BH4: 11 | BI4: 10 | BJ4: 9 | BK4: 4 | BL4: 4 | BM4: 9 | BN4: 12 | BO4: 4 | BP4: 4 | BQ4: 5 | BR4: 6 | BS4: 10 | BT4: 3 | BU4: 0 | BV4: 8 | BW4: 4 | BX4: 3 | BY4: 3 | BZ4: 10 | CA4: 13 | CB4: 10 | CC4: 5 | CD4: 5 | CE4: 3 | CF4: 9 | CG4: 3 | CH4: 7 | CI4: 6 | CJ4: 14 | CK4: 14 | CL4: 6 | CM4: 4 | CN4: 8 | CO4: 9 | CP4: 12 | CQ4: 2 | CR4: 7 | CS4: 8 | CT4: 1 | CU4: 6 | CV4: 6 | CW4: 9 | CX4: 10 | CY4: 9 | CZ4: 9 | DA4: 2 | DB4: 5 | DC4: 6 | DD4: 9 | DE4: 9 | DF4: 10 | DG4: 6 | DH4: 9 | DI4: 10 | DJ4: 13 | DK4: 8 | DL4: 8 | DM4: 5 | DN4: 8 | DO4: 9 | DP4: 9 | DQ4: 10 | DR4: 11 | DS4: 3 | DT4: 11 | DU4: 11 | DV4: 9 | DW4: 13 | DX4: 10 | DY4: 10 | DZ4: 9 | EA4: 12 | EB4: 12 | EC4: 15 | ED4: 9 | EE4: 7 | EF4: 6 | EG4: 5 | EH4: 6 | EI4: 6 | EJ4: 12 | EK4: 5 | EL4: 8 | EM4: 6 | EN4: 7 | EO4: 8 | EP4: 10 | EQ4: 5 | ER4: 6 | ES4: 6 | ET4: 6 | EU4: 8 | EV4: 8 | EW4: 4 | EX4: 4 | EY4: 7 | EZ4: 5 | FA4: 11 | FB4: 7 | FC4: 7 | FD4: 7 | FE4: 4 | FF4: 4 | FG4: 10 | FH4: 6 | FI4: 10 | FJ4: 8 | FK4: 11 | FL4: 11 | FM4: 11 | FN4: 10 | FO4: 10 | FP4: 9 | FQ4: 9 | FR4: 6 | FS4: 6 | FT4: 6 | FU4: 6 | FV4: 9 | FW4: 8 | FX4: 5 | FY4: 5 | FZ4: 10 | GA4: 10 | GB4: 8 | GC4: 6 | GD4: 6 | GE4: 3 | GF4: 5 | GG4: 9 | GH4: 10 | GI4: 8 | GJ4: 7 | GK4: 7 | GL4: 7 | GM4: 11 | GN4: 6 | GO4: 12 | GP4: 12 | GQ4: 7 | GR4: 7 | GS4: 7 | GT4: 5 | GU4: 6
A5: 100217 | B5: 4 | C5: 4 | D5: 12 | E5: 18 | F5: 4 | G5: 4 | H5: 4 | I5: 4 | J5: 4 | K5: 3 | L5: 5 | M5: 7 | N5: 5 | O5: 5 | P5: 9 | Q5: 8 | R5: 11 | S5: 11 | T5: 4 | U5: 7 | V5: 13 | W5: 1 | X5: 9 | Y5: 5 | Z5: 6 | AA5: 5 | AB5: 6 | AC5: 8 | AD5: 8 | AE5: 3 | AF5: 6 | AG5: 1 | AH5: 2 | AI5: 1 | AJ5: 7 | AK5: 4 | AL5: 7 | AM5: 5 | AN5: 8 | AO5: 4 | AP5: 5 | AQ5: 6 | AR5: 8 | AS5: 6 | AT5: 6 | AU5: 8 | AV5: 5 | AW5: 1 | AX5: 6 | AY5: 6 | AZ5: 6 | BA5: 2 | BB5: 8 | BC5: 4 | BD5: 11 | BE5: 9 | BF5: 7 | BG5: 6 | BH5: 8 | BI5: 9 | BJ5: 8 | BK5: 3 | BL5: 4 | BM5: 7 | BN5: 11 | BO5: 4 | BP5: 4 | BQ5: 5 | BR5: 6 | BS5: 10 | BT5: 1 | BU5: 0 | BV5: 5 | BW5: 3 | BX5: 3 | BY5: 3 | BZ5: 10 | CA5: 7 | CB5: 10 | CC5: 5 | CD5: 6 | CE5: 2 | CF5: 10 | CG5: 2 | CH5: 8 | CI5: 7 | CJ5: 11 | CK5: 11 | CL5: 5 | CM5: 3 | CN5: 7 | CO5: 8 | CP5: 10 | CQ5: 2 | CR5: 4 | CS5: 6 | CT5: 1 | CU5: 6 | CV5: 6 | CW5: 5 | CX5: 7 | CY5: 7 | CZ5: 10 | DA5: 1 | DB5: 5 | DC5: 5 | DD5: 6 | DE5: 7 | DF5: 7 | DG5: 6 | DH5: 9 | DI5: 7 | DJ5: 9 | DK5: 7 | DL5: 5 | DM5: 4 | DN5: 5 | DO5: 6 | DP5: 6 | DQ5: 5 | DR5: 8 | DS5: 2 | DT5: 11 | DU5: 12 | DV5: 6 | DW5: 7 | DX5: 7 | DY5: 7 | DZ5: 7 | EA5: 10 | EB5: 8 | EC5: 13 | ED5: 6 | EE5: 5 | EF5: 5 | EG5: 4 | EH5: 5 | EI5: 5 | EJ5: 8 | EK5: 4 | EL5: 6 | EM5: 6 | EN5: 4 | EO5: 5 | EP5: 7 | EQ5: 4 | ER5: 7 | ES5: 5 | ET5: 6 | EU5: 5 | EV5: 6 | EW5: 3 | EX5: 3 | EY5: 5 | EZ5: 3 | FA5: 7 | FB5: 4 | FC5: 4 | FD5: 4 | FE5: 4 | FF5: 4 | FG5: 7 | FH5: 5 | FI5: 10 | FJ5: 6 | FK5: 8 | FL5: 12 | FM5: 7 | FN5: 7 | FO5: 7 | FP5: 7 | FQ5: 7 | FR5: 5 | FS5: 6 | FT5: 6 | FU5: 6 | FV5: 9 | FW5: 8 | FX5: 4 | FY5: 4 | FZ5: 10 | GA5: 8 | GB5: 8 | GC5: 5 | GD5: 5 | GE5: 2 | GF5: 6 | GG5: 8 | GH5: 10 | GI5: 7 | GJ5: 6 | GK5: 6 | GL5: 6 | GM5: 10 | GN5: 5 | GO5: 10 | GP5: 10 | GQ5: 6 | GR5: 6 | GS5: 6 | GT5: 5 | GU5: 8
A6: 100728 | B6: 4 | C6: 4 | D6: 5 | E6: 4 | F6: 11 | G6: 11 | H6: 9 | I6: 10 | J6: 8 | K6: 3 | L6: 2 | M6: 4 | N6: 4 | O6: 4 | P6: 5 | Q6: 7 | R6: 5 | S6: 5 | T6: 3 | U6: 5 | V6: 6 | W6: 1 | X6: 7 | Y6: 4 | Z6: 4 | AA6: 3 | AB6: 5 | AC6: 6 | AD6: 3 | AE6: 2 | AF6: 5 | AG6: 1 | AH6: 1 | AI6: 3 | AJ6: 5 | AK6: 4 | AL6: 4 | AM6: 3 | AN6: 3 | AO6: 2 | AP6: 2 | AQ6: 0 | AR6: 1 | AS6: 5 | AT6: 5 | AU6: 7 | AV6: 3 | AW6: 1 | AX6: 3 | AY6: 3 | AZ6: 3 | BA6: 3 | BB6: 3 | BC6: 4 | BD6: 5 | BE6: 3 | BF6: 3 | BG6: 3 | BH6: 7 | BI6: 4 | BJ6: 4 | BK6: 6 | BL6: 6 | BM6: 4 | BN6: 7 | BO6: 3 | BP6: 4 | BQ6: 6 | BR6: 6 | BS6: 5 | BT6: 0 | BU6: 0 | BV6: 3 | BW6: 5 | BX6: 6 | BY6: 6 | BZ6: 5 | CA6: 6 | CB6: 5 | CC6: 3 | CD6: 4 | CE6: 2 | CF6: 5 | CG6: 4 | CH6: 1 | CI6: 1 | CJ6: 4 | CK6: 4 | CL6: 5 | CM6: 5 | CN6: 7 | CO6: 4 | CP6: 5 | CQ6: 1 | CR6: 3 | CS6: 4 | CT6: 0 | CU6: 3 | CV6: 3 | CW6: 4 | CX6: 5 | CY6: 5 | CZ6: 3 | DA6: 1 | DB6: 2 | DC6: 1 | DD6: 3 | DE6: 4 | DF6: 5 | DG6: 4 | DH6: 3 | DI6: 4 | DJ6: 5 | DK6: 4 | DL6: 4 | DM6: 1 | DN6: 4 | DO6: 3 | DP6: 3 | DQ6: 4 | DR6: 4 | DS6: 4 | DT6: 5 | DU6: 5 | DV6: 3 | DW6: 3 | DX6: 4 | DY6: 4 | DZ6: 3 | EA6: 6 | EB6: 5 | EC6: 6 | ED6: 3 | EE6: 3 | EF6: 1 | EG6: 3 | EH6: 2 | EI6: 1 | EJ6: 5 | EK6: 3 | EL6: 4 | EM6: 2 | EN6: 2 | EO6: 3 | EP6: 4 | EQ6: 6 | ER6: 2 | ES6: 1 | ET6: 6 | EU6: 4 | EV6: 4 | EW6: 1 | EX6: 1 | EY6: 3 | EZ6: 3 | FA6: 5 | FB6: 2 | FC6: 2 | FD6: 2 | FE6: 8 | FF6: 2 | FG6: 5 | FH6: 1 | FI6: 4 | FJ6: 3 | FK6: 4 | FL6: 5 | FM6: 5 | FN6: 4 | FO6: 4 | FP6: 3 | FQ6: 3 | FR6: 2 | FS6: 3 | FT6: 3 | FU6: 2 | FV6: 4 | FW6: 4 | FX6: 5 | FY6: 5 | FZ6: 4 | GA6: 5 | GB6: 5 | GC6: 1 | GD6: 1 | GE6: 5 | GF6: 4 | GG6: 7 | GH6: 4 | GI6: 7 | GJ6: 1 | GK6: 1 | GL6: 1 | GM6: 5 | GN6: 1 | GO6: 5 | GP6: 5 | GQ6: 1 | GR6: 1 | GS6: 1 | GT6: 2 | GU6: 4
A7: 100733 | B7: 4 | C7: 4 | D7: 5 | E7: 4 | F7: 11 | G7: 11 | H7: 9 | I7: 10 | J7: 8 | K7: 3 | L7: 2 | M7: 4 | N7: 4 | O7: 4 | P7: 5 | Q7: 7 | R7: 5 | S7: 5 | T7: 3 | U7: 5 | V7: 6 | W7: 1 | X7: 7 | Y7: 4 | Z7: 4 | AA7: 3 | AB7: 5 | AC7: 6 | AD7: 3 | AE7: 2 | AF7: 5 | AG7: 1 | AH7: 1 | AI7: 3 | AJ7: 5 | AK7: 4 | AL7: 4 | AM7: 3 | AN7: 3 | AO7: 2 | AP7: 2 | AQ7: 0 | AR7: 1 | AS7: 5 | AT7: 5 | AU7: 7 | AV7: 3 | AW7: 1 | AX7: 3 | AY7: 3 | AZ7: 3 | BA7: 3 | BB7: 3 | BC7: 4 | BD7: 5 | BE7: 3 | BF7: 3 | BG7: 3 | BH7: 7 | BI7: 4 | BJ7: 4 | BK7: 6 | BL7: 6 | BM7: 4 | BN7: 7 | BO7: 3 | BP7: 4 | BQ7: 6 | BR7: 6 | BS7: 5 | BT7: 0 | BU7: 0 | BV7: 3 | BW7: 5 | BX7: 6 | BY7: 6 | BZ7: 5 | CA7: 6 | CB7: 5 | CC7: 3 | CD7: 4 | CE7: 2 | CF7: 5 | CG7: 4 | CH7: 1 | CI7: 1 | CJ7: 4 | CK7: 4 | CL7: 5 | CM7: 5 | CN7: 7 | CO7: 4 | CP7: 5 | CQ7: 1 | CR7: 3 | CS7: 4 | CT7: 0 | CU7: 3 | CV7: 3 | CW7: 4 | CX7: 5 | CY7: 5 | CZ7: 3 | DA7: 1 | DB7: 2 | DC7: 1 | DD7: 3 | DE7: 4 | DF7: 5 | DG7: 4 | DH7: 3 | DI7: 4 | DJ7: 5 | DK7: 4 | DL7: 4 | DM7: 1 | DN7: 4 | DO7: 3 | DP7: 3 | DQ7: 4 | DR7: 4 | DS7: 4 | DT7: 5 | DU7: 5 | DV7: 3 | DW7: 3 | DX7: 4 | DY7: 4 | DZ7: 3 | EA7: 6 | EB7: 5 | EC7: 6 | ED7: 3 | EE7: 3 | EF7: 1 | EG7: 3 | EH7: 2 | EI7: 1 | EJ7: 5 | EK7: 3 | EL7: 4 | EM7: 2 | EN7: 2 | EO7: 3 | EP7: 4 | EQ7: 6 | ER7: 2 | ES7: 1 | ET7: 6 | EU7: 4 | EV7: 4 | EW7: 1 | EX7: 1 | EY7: 3 | EZ7: 3 | FA7: 5 | FB7: 2 | FC7: 2 | FD7: 2 | FE7: 8 | FF7: 2 | FG7: 5 | FH7: 1 | FI7: 4 | FJ7: 3 | FK7: 4 | FL7: 5 | FM7: 5 | FN7: 4 | FO7: 4 | FP7: 3 | FQ7: 3 | FR7: 2 | FS7: 3 | FT7: 3 | FU7: 2 | FV7: 4 | FW7: 4 | FX7: 5 | FY7: 5 | FZ7: 4 | GA7: 5 | GB7: 5 | GC7: 1 | GD7: 1 | GE7: 5 | GF7: 4 | GG7: 7 | GH7: 4 | GI7: 7 | GJ7: 1 | GK7: 1 | GL7: 1 | GM7: 5 | GN7: 1 | GO7: 5 | GP7: 5 | GQ7: 1 | GR7: 1 | GS7: 1 | GT7: 2 | GU7: 4
A8: 100735 | B8: 4 | C8: 4 | D8: 5 | E8: 4 | F8: 9 | G8: 9 | H8: 11 | I8: 9 | J8: 7 | K8: 3 | L8: 2 | M8: 4 | N8: 4 | O8: 4 | P8: 5 | Q8: 7 | R8: 5 | S8: 5 | T8: 3 | U8: 5 | V8: 6 | W8: 1 | X8: 8 | Y8: 4 | Z8: 4 | AA8: 3 | AB8: 6 | AC8: 6 | AD8: 3 | AE8: 2 | AF8: 5 | AG8: 1 | AH8: 1 | AI8: 3 | AJ8: 5 | AK8: 4 | AL8: 4 | AM8: 3 | AN8: 3 | AO8: 2 | AP8: 2 | AQ8: 0 | AR8: 1 | AS8: 5 | AT8: 5 | AU8: 7 | AV8: 3 | AW8: 1 | AX8: 4 | AY8: 4 | AZ8: 3 | BA8: 3 | BB8: 3 | BC8: 4 | BD8: 5 | BE8: 3 | BF8: 3 | BG8: 3 | BH8: 8 | BI8: 4 | BJ8: 4 | BK8: 7 | BL8: 6 | BM8: 4 | BN8: 7 | BO8: 3 | BP8: 4 | BQ8: 5 | BR8: 5 | BS8: 5 | BT8: 0 | BU8: 0 | BV8: 3 | BW8: 5 | BX8: 6 | BY8: 5 | BZ8: 5 | CA8: 6 | CB8: 5 | CC8: 3 | CD8: 4 | CE8: 2 | CF8: 5 | CG8: 4 | CH8: 1 | CI8: 1 | CJ8: 4 | CK8: 4 | CL8: 5 | CM8: 4 | CN8: 6 | CO8: 4 | CP8: 5 | CQ8: 1 | CR8: 3 | CS8: 5 | CT8: 0 | CU8: 3 | CV8: 3 | CW8: 4 | CX8: 5 | CY8: 5 | CZ8: 3 | DA8: 1 | DB8: 2 | DC8: 1 | DD8: 4 | DE8: 4 | DF8: 6 | DG8: 4 | DH8: 3 | DI8: 4 | DJ8: 5 | DK8: 4 | DL8: 4 | DM8: 1 | DN8: 4 | DO8: 4 | DP8: 4 | DQ8: 4 | DR8: 4 | DS8: 4 | DT8: 5 | DU8: 5 | DV8: 4 | DW8: 4 | DX8: 5 | DY8: 5 | DZ8: 3 | EA8: 6 | EB8: 5 | EC8: 6 | ED8: 3 | EE8: 3 | EF8: 1 | EG8: 3 | EH8: 2 | EI8: 1 | EJ8: 5 | EK8: 3 | EL8: 4 | EM8: 2 | EN8: 2 | EO8: 3 | EP8: 4 | EQ8: 5 | ER8: 2 | ES8: 1 | ET8: 5 | EU8: 4 | EV8: 4 | EW8: 1 | EX8: 1 | EY8: 3 | EZ8: 3 | FA8: 5 | FB8: 2 | FC8: 2 | FD8: 2 | FE8: 7 | FF8: 2 | FG8: 5 | FH8: 1 | FI8: 4 | FJ8: 3 | FK8: 4 | FL8: 5 | FM8: 5 | FN8: 5 | FO8: 5 | FP8: 3 | FQ8: 3 | FR8: 2 | FS8: 3 | FT8: 3 | FU8: 2 | FV8: 4 | FW8: 4 | FX8: 5 | FY8: 5 | FZ8: 4 | GA8: 5 | GB8: 5 | GC8: 1 | GD8: 1 | GE8: 4 | GF8: 4 | GG8: 6 | GH8: 4 | GI8: 6 | GJ8: 1 | GK8: 1 | GL8: 1 | GM8: 5 | GN8: 1 | GO8: 5 | GP8: 5 | GQ8: 1 | GR8: 1 | GS8: 1 | GT8: 2 | GU8: 4
A9: 100743 | B9: 4 | C9: 4 | D9: 5 | E9: 4 | F9: 10 | G9: 10 | H9: 9 | I9: 11 | J9: 8 | K9: 3 | L9: 2 | M9: 4 | N9: 4 | O9: 4 | P9: 5 | Q9: 7 | R9: 5 | S9: 5 | T9: 3 | U9: 5 | V9: 6 | W9: 1 | X9: 7 | Y9: 4 | Z9: 4 | AA9: 3 | AB9: 5 | AC9: 6 | AD9: 3 | AE9: 2 | AF9: 5 | AG9: 1 | AH9: 1 | AI9: 3 | AJ9: 5 | AK9: 4 | AL9: 4 | AM9: 3 | AN9: 3 | AO9: 2 | AP9: 2 | AQ9: 0 | AR9: 1 | AS9: 5 | AT9: 5 | AU9: 7 | AV9: 3 | AW9: 1 | AX9: 3 | AY9: 3 | AZ9: 3 | BA9: 3 | BB9: 3 | BC9: 4 | BD9: 5 | BE9: 3 | BF9: 3 | BG9: 3 | BH9: 7 | BI9: 4 | BJ9: 4 | BK9: 6 | BL9: 6 | BM9: 4 | BN9: 7 | BO9: 3 | BP9: 4 | BQ9: 5 | BR9: 5 | BS9: 5 | BT9: 0 | BU9: 0 | BV9: 3 | BW9: 5 | BX9: 6 | BY9: 6 | BZ9: 5 | CA9: 6 | CB9: 5 | CC9: 3 | CD9: 4 | CE9: 2 | CF9: 5 | CG9: 4 | CH9: 1 | CI9: 1 | CJ9: 4 | CK9: 4 | CL9: 5 | CM9: 4 | CN9: 6 | CO9: 4 | CP9: 5 | CQ9: 1 | CR9: 3 | CS9: 4 | CT9: 0 | CU9: 3 | CV9: 3 | CW9: 4 | CX9: 5 | CY9: 5 | CZ9: 3 | DA9: 1 | DB9: 2 | DC9: 1 | DD9: 3 | DE9: 4 | DF9: 5 | DG9: 4 | DH9: 3 | DI9: 4 | DJ9: 5 | DK9: 4 | DL9: 4 | DM9: 1 | DN9: 4 | DO9: 3 | DP9: 3 | DQ9: 4 | DR9: 4 | DS9: 4 | DT9: 5 | DU9: 5 | DV9: 3 | DW9: 3 | DX9: 4 | DY9: 4 | DZ9: 3 | EA9: 6 | EB9: 5 | EC9: 6 | ED9: 3 | EE9: 3 | EF9: 1 | EG9: 3 | EH9: 2 | EI9: 1 | EJ9: 5 | EK9: 3 | EL9: 4 | EM9: 2 | EN9: 2 | EO9: 3 | EP9: 4 | EQ9: 5 | ER9: 2 | ES9: 1 | ET9: 5 | EU9: 4 | EV9: 4 | EW9: 1 | EX9: 1 | EY9: 3 | EZ9: 3 | FA9: 5 | FB9: 2 | FC9: 2 | FD9: 2 | FE9: 8 | FF9: 2 | FG9: 5 | FH9: 1 | FI9: 4 | FJ9: 3 | FK9: 4 | FL9: 5 | FM9: 5 | FN9: 4 | FO9: 4 | FP9: 3 | FQ9: 3 | FR9: 2 | FS9: 3 | FT9: 3 | FU9: 2 | FV9: 4 | FW9: 4 | FX9: 5 | FY9: 5 | FZ9: 4 | GA9: 5 | GB9: 5 | GC9: 1 | GD9: 1 | GE9: 4 | GF9: 4 | GG9: 6 | GH9: 4 | GI9: 6 | GJ9: 1 | GK9: 1 | GL9: 1 | GM9: 5 | GN9: 1 | GO9: 5 | GP9: 5 | GQ9: 1 | GR9: 1 | GS9: 1 | GT9: 2 | GU9: 4
A10: 100746 | B10: 3 | C10: 3 | D10: 4 | E10: 4 | F10: 8 | G10: 8 | H10: 7 | I10: 8 | J10: 11 | K10: 2 | L10: 3 | M10: 3 | N10: 5 | O10: 5 | P10: 4 | Q10: 5 | R10: 4 | S10: 4 | T10: 1 | U10: 4 | V10: 4 | W10: 0 | X10: 5 | Y10: 2 | Z10: 2 | AA10: 2 | AB10: 4 | AC10: 5 | AD10: 3 | AE10: 2 | AF10: 4 | AG10: 1 | AH10: 1 | AI10: 1 | AJ10: 3 | AK10: 4 | AL10: 3 | AM10: 3 | AN10: 3 | AO10: 2 | AP10: 2 | AQ10: 0 | AR10: 1 | AS10: 5 | AT10: 5 | AU10: 5 | AV10: 3 | AW10: 0 | AX10: 2 | AY10: 2 | AZ10: 2 | BA10: 3 | BB10: 3 | BC10: 5 | BD10: 4 | BE10: 3 | BF10: 3 | BG10: 3 | BH10: 5 | BI10: 3 | BJ10: 4 | BK10: 4 | BL10: 4 | BM10: 3 | BN10: 5 | BO10: 4 | BP10: 3 | BQ10: 4 | BR10: 4 | BS10: 5 | BT10: 0 | BU10: 1 | BV10: 2 | BW10: 5 | BX10: 5 | BY10: 5 | BZ10: 5 | CA10: 5 | CB10: 5 | CC10: 1 | CD10: 4 | CE10: 2 | CF10: 5 | CG10: 2 | CH10: 1 | CI10: 1 | CJ10: 4 | CK10: 4 | CL10: 5 | CM10: 3 | CN10: 5 | CO10: 4 | CP10: 4 | CQ10: 2 | CR10: 2 | CS10: 3 | CT10: 0 | CU10: 3 | CV10: 3 | CW10: 3 | CX10: 3 | CY10: 4 | CZ10: 3 | DA10: 0 | DB10: 3 | DC10: 1 | DD10: 2 | DE10: 3 | DF10: 3 | DG10: 3 | DH10: 4 | DI10: 3 | DJ10: 4 | DK10: 4 | DL10: 3 | DM10: 1 | DN10: 3 | DO10: 2 | DP10: 2 | DQ10: 4 | DR10: 3 | DS10: 2 | DT10: 5 | DU10: 5 | DV10: 2 | DW10: 2 | DX10: 3 | DY10: 3 | DZ10: 3 | EA10: 4 | EB10: 4 | EC10: 4 | ED10: 2 | EE10: 2 | EF10: 1 | EG10: 2 | EH10: 2 | EI10: 1 | EJ10: 4 | EK10: 2 | EL10: 3 | EM10: 3 | EN10: 1 | EO10: 2 | EP10: 3 | EQ10: 4 | ER10: 2 | ES10: 1 | ET10: 4 | EU10: 2 | EV10: 3 | EW10: 1 | EX10: 1 | EY10: 2 | EZ10: 2 | FA10: 3 | FB10: 1 | FC10: 1 | FD10: 1 | FE10: 9 | FF10: 2 | FG10: 3 | FH10: 1 | FI10: 4 | FJ10: 3 | FK10: 3 | FL10: 5 | FM10: 4 | FN10: 3 | FO10: 3 | FP10: 3 | FQ10: 3 | FR10: 2 | FS10: 3 | FT10: 3 | FU10: 2 | FV10: 4 | FW10: 4 | FX10: 4 | FY10: 5 | FZ10: 4 | GA10: 5 | GB10: 5 | GC10: 1 | GD10: 1 | GE10: 3 | GF10: 4 | GG10: 5 | GH10: 4 | GI10: 5 | GJ10: 1 | GK10: 1 | GL10: 1 | GM10: 5 | GN10: 1 | GO10: 4 | GP10: 4 | GQ10: 1 | GR10: 1 | GS10: 1 | GT10: 2 | GU10: 3
A11: 101944 | B11: 3 | C11: 3 | D11: 6 | E11: 3 | F11: 3 | G11: 3 | H11: 3 | I11: 3 | J11: 2 | K11: 19 | L11: 2 | M11: 2 | N11: 2 | O11: 2 | P11: 6 | Q11: 7 | R11: 4 | S11: 4 | T11: 6 | U11: 2 | V11: 6 | W11: 0 | X11: 7 | Y11: 5 | Z11: 4 | AA11: 2 | AB11: 5 | AC11: 6 | AD11: 2 | AE11: 0 | AF11: 6 | AG11: 2 | AH11: 0 | AI11: 2 | AJ11: 4 | AK11: 1 | AL11: 3 | AM11: 1 | AN11: 4 | AO11: 1 | AP11: 2 | AQ11: 2 | AR11: 1 | AS11: 2 | AT11: 2 | AU11: 6 | AV11: 3 | AW11: 0 | AX11: 3 | AY11: 3 | AZ11: 3 | BA11: 0 | BB11: 6 | BC11: 2 | BD11: 6 | BE11: 3 | BF11: 3 | BG11: 3 | BH11: 7 | BI11: 5 | BJ11: 5 | BK11: 4 | BL11: 3 | BM11: 6 | BN11: 6 | BO11: 2 | BP11: 2 | BQ11: 4 | BR11: 3 | BS11: 5 | BT11: 1 | BU11: 0 | BV11: 4 | BW11: 1 | BX11: 2 | BY11: 3 | BZ11: 5 | CA11: 7 | CB11: 5 | CC11: 6 | CD11: 3 | CE11: 1 | CF11: 4 | CG11: 3 | CH11: 1 | CI11: 1 | CJ11: 6 | CK11: 6 | CL11: 3 | CM11: 1 | CN11: 4 | CO11: 5 | CP11: 4 | CQ11: 1 | CR11: 5 | CS11: 4 | CT11: 0 | CU11: 2 | CV11: 3 | CW11: 7 | CX11: 4 | CY11: 4 | CZ11: 2 | DA11: 0 | DB11: 0 | DC11: 5 | DD11: 3 | DE11: 4 | DF11: 4 | DG11: 4 | DH11: 6 | DI11: 3 | DJ11: 6 | DK11: 5 | DL11: 7 | DM11: 4 | DN11: 7 | DO11: 3 | DP11: 3 | DQ11: 7 | DR11: 2 | DS11: 3 | DT11: 4 | DU11: 4 | DV11: 3 | DW11: 4 | DX11: 3 | DY11: 3 | DZ11: 3 | EA11: 6 | EB11: 3 | EC11: 6 | ED11: 2 | EE11: 1 | EF11: 4 | EG11: 1 | EH11: 1 | EI11: 4 | EJ11: 3 | EK11: 4 | EL11: 4 | EM11: 0 | EN11: 0 | EO11: 2 | EP11: 3 | EQ11: 2 | ER11: 0 | ES11: 4 | ET11: 3 | EU11: 3 | EV11: 4 | EW11: 4 | EX11: 4 | EY11: 1 | EZ11: 1 | FA11: 4 | FB11: 2 | FC11: 2 | FD11: 2 | FE11: 2 | FF11: 3 | FG11: 4 | FH11: 5 | FI11: 5 | FJ11: 3 | FK11: 2 | FL11: 4 | FM11: 3 | FN11: 3 | FO11: 3 | FP11: 3 | FQ11: 3 | FR11: 3 | FS11: 3 | FT11: 3 | FU11: 3 | FV11: 3 | FW11: 2 | FX11: 2 | FY11: 2 | FZ11: 4 | GA11: 5 | GB11: 2 | GC11: 4 | GD11: 4 | GE11: 2 | GF11: 3 | GG11: 4 | GH11: 4 | GI11: 4 | GJ11: 4 | GK11: 4 | GL11: 4 | GM11: 4 | GN11: 4 | GO11: 4 | GP11: 4 | GQ11: 4 | GR11: 4 | GS11: 4 | GT11: 0 | GU11: 3
